Workbook

Sheet SIGNAL Refresh
D2: NATIONAL CADET CORPS | X2: NATIONAL CADET CORPS | AV2: NATIONAL CADET CORPS | BT2: NATIONAL CADET CORPS | CN2: NATIONAL CADET CORPS | DL2: NATIONAL CADET CORPS | EJ2: NATIONAL CADET CORPS
A3: Unit:4 (TN) CTC NCC, Annamalainagar | L3: Place: | M3: Annamalainagar | U3: Unit:4 (TN) CTC NCC, Annamalainagar | AJ3: Place: | AK3: Annamalainagar | AS3: Unit:4 (TN) CTC NCC, Annamalainagar | BH3: Place: | BI3: Annamalainagar | BQ3: Unit:4 (TN) CTC NCC, Annamalainagar | CB3: Place: | CC3: Annamalainagar | CK3: Unit:4 (TN) CTC NCC, Annamalainagar | CZ3: Place: | DA3: Annamalainagar | DI3: Unit:4 (TN) CTC NCC, Annamalainagar | DX3: Place: | DY3: Annamalainagar | EG3: Unit:4 (TN) CTC NCC, Annamalainagar | FD3: Place: | FE3: Annamalainagar
D4: Attendance Register for the month of JULY 2024 | I4: Total number of Parades held in this month: | P4: No.:4 In Hrs:8 | X4: Attendance Register for the month of AUGUST 2023 | AG4: Total number of Parades held in this month: | AN4: No.:8 In Hrs:16 | AV4: Attendance Register for the month of SEPTEMBER 2023 | BE4: Total number of Parades held in this month:6 | BL4: No.:8 In Hrs:16 | BT4: Attendance Register for the month of OCTOBER 2023 | BY4: Total number of Parades held in this month: | CF4: No.: 4 In Hrs: 8 | CN4: Attendance Register for the month of December 2022 | CW4: Total number of Parades held in this month:5 | DD4: No.:5 In Hrs:10 | DL4: Attendance Register for the month of January 2023 | DU4: Total number of Parades held in this month:6 | EB4: No.:6 In Hrs:12 | EJ4: Attendance Register for the month of February 2023 | FA4: Total number of Parades held in this month:4 | FH4: No.:4 In Hrs:8
A5: College/Institution: | D5: FEAT,Annamalai University (Signal) | U5: College/Institution: | X5: FEAT,Annamalai University (Signal) | AS5: College/Institution: | AV5: FEAT,Annamalai University (Signal) | BQ5: College/Institution: | BT5: FEAT,Annamalai University (Signal) | CK5: College/Institution: | CN5: FEAT,Annamalai University (Signal) | DI5: College/Institution: | DL5: FEAT,Annamalai University (Signal) | EG5: College/Institution: | EJ5: FEAT,Annamalai University (Signal)
A7: Serial number | B7: Cadet number | C7: Rank | D7: Name | E7: Date of Parades | I7: Total number of Parades | K7: Percentage of Attendance | L7: Allowance due to cadets for the month | P7: Progressive total including amount claimed in this bill | T7: Remarks | U7: Serial number | V7: Cadet number | W7: Rank | X7: Name | Y7: Date of Parades | AG7: Total number of Parades | AI7: Percentage of Attendance | AJ7: Allowance due to cadets for the month | AN7: Progressive total including amount claimed in this bill | AR7: Remarks | AS7: Serial number | AT7: Cadet number | AU7: Rank | AV7: Name | AW7: Date of Parades | BE7: Total number of Parades | BG7: Percentage of Attendance | BH7: Allowance due to cadets for the month | BL7: Progressive total including amount claimed in this bill | BP7: Remarks | BQ7: Serial number | BR7: Cadet number | BS7: Rank | BT7: Name | BU7: Date of Parades | BY7: Total number of Parades | CA7: Percentage of Attendance | CB7: Allowance due to cadets for the month | CF7: Progressive total including amount claimed in this bill | CJ7: Remarks | CK7: Serial number | CL7: Cadet number | CM7: Rank | CN7: Name | CP7: Date of Parades | CW7: Total number of Parades | CY7: Percentage of Attendance | CZ7: Allowance due to cadets for the month | DD7: Progressive total including amount claimed in this bill | DH7: Remarks | DI7: Serial number | DJ7: Cadet number | DK7: Rank | DL7: Name | DM7: Date of Parades | DU7: Total number of Parades | DW7: Percentage of Attendance | DX7: Allowance due to cadets for the month | EB7: Progressive total including amount claimed in this bill | EF7: Remarks | EG7: Serial number | EH7: Cadet number | EI7: Rank | EJ7: Name | EK7: Date of Parades | FA7: Total number of Parades | FC7: Percentage of Attendance | FD7: Allowance due to cadets for the month | FH7: Progressive total including amount claimed in this bill | FL7: Remarks
E8: Dates | Y8: Dates | AW8: Dates | BU8: Dates | CP8: Dates | DM8: Dates | EK8: Dates
E9: 8 | F9: 9 | G9: 10 | H9: 11 | I9: Attended | J9: In Hours | L9: Refreshment at paper hour | N9: Washing | P9: Refreshment | R9: Washing | Y9: 1 | Z9: 2 | AA9: 3 | AB9: 9 | AC9: 10 | AD9: 11 | AE9: 14 | AF9: 15 | AG9: Attended | AH9: In Hours | AJ9: Refreshment at paper hour | AL9: Washing | AN9: Refreshment | AP9: Washing | AW9: 12 | AX9: 13 | AY9: 14 | AZ9: 20 | BA9: 21 | BB9: 22 | BC9: 25 | BD9: 26 | BE9: Attended | BF9: In Hours | BH9: Refreshment at paper hour | BJ9: Washing | BL9: Refreshment | BN9: Washing | BU9: 3 | BV9: 4 | BW9: 10 | BX9: 11 | BY9: Attended | BZ9: In Hours | CB9: Refreshment at paper hour | CD9: Washing | CF9: Refreshment | CH9: Washing | CO9: 7 | CP9: 8 | CQ9: 13 | CR9: 14 | CS9: 15 | CW9: Attended | CX9: In Hours | CZ9: Refreshment at paper hour | DB9: Washing | DD9: Refreshment | DF9: Washing | DM9: 4 | DN9: 5 | DO9: 18 | DP9: 19 | DQ9: 20 | DR9: 21 | DU9: Attended | DV9: In Hours | DX9: Refreshment at paper hour | DZ9: Washing | EB9: Refreshment | ED9: Washing | EK9: 1 | EL9: 2 | EM9: 3 | EN9: 6 | FA9: Attended | FB9: In Hours | FD9: Refreshment at paper hour | FF9: Washing | FH9: Refreshment | FJ9: Washing
E10: 2 | F10: 2 | G10: 2 | H10: 2 | Y10: 2 | Z10: 2 | AA10: 2 | AB10: 2 | AC10: 2 | AD10: 2 | AE10: 2 | AF10: 2 | AW10: 2 | AX10: 2 | AY10: 2 | AZ10: 2 | BA10: 2 | BB10: 2 | BU10: 2 | BV10: 2 | BW10: 2 | BX10: 2 | CO10: 2 | CP10: 2 | CQ10: 2 | CR10: 2 | CS10: 2 | DM10: 2 | DN10: 2 | DO10: 2 | DP10: 2 | DQ10: 2 | DR10: 2 | DS10: 2 Hours | EK10: 2 | EL10: 2 | EM10: 2 Hours | EN10: 2 | FN10: Total parade | FO10: % Attendence
L11: Rs | M11: P | N11: Rs | O11: P | P11: Rs | Q11: P | R11: Rs | S11: P | AJ11: Rs | AK11: P | AL11: Rs | AM11: P | AN11: Rs | AO11: P | AP11: Rs | AQ11: P | BH11: Rs | BI11: P | BJ11: Rs | BK11: P | BL11: Rs | BM11: P | BN11: Rs | BO11: P | CB11: Rs | CC11: P | CD11: Rs | CE11: P | CF11: Rs | CG11: P | CH11: Rs | CI11: P | CZ11: Rs | DA11: P | DB11: Rs | DC11: P | DD11: Rs | DE11: P | DF11: Rs | DG11: P | DX11: Rs | DY11: P | DZ11: Rs | EA11: P | EB11: Rs | EC11: P | ED11: Rs | EE11: P | FD11: Rs | FE11: P | FF11: Rs | FG11: P | FH11: Rs | FI11: P | FJ11: Rs | FK11: P
A12: 1 | B12: TN22SDA894031 | C12: CDT | D12: AJITH KUMAR.K | E12: A | F12: A | G12: A | H12: A | I12: =COUNT(E12:H12) -> 0 | J12: =I12*2 -> 0 | K12: =I12/4*100 -> 0 | L12: =I12*50 -> 0 | N12: =IF(K12<=40,0,IF(K12<=60,5,IF(K12>=61,10))) -> 0 | P12: =L12 -> 0 | R12: =N12 -> 0 | U12: 1 | V12: TN22SDA894031 | W12: CDT | X12: AJITH KUMAR.K | Y12: 12 | Z12: 15 | AA12: 18 | AB12: A | AC12: 21 | AD12: 24 | AE12: 27 | AF12: 30 | AG12: =COUNT(Y12:AF12) -> 7 | AH12: =AG12*2 -> 14 | AI12: =AG12/8*100 -> 87.5 | AJ12: =AG12*50 -> 350 | AL12: =IF(AI12<=40,0,IF(AI12<=60,5,IF(AI12>=61,10))) -> 10 | AN12: =P12+AJ12 -> 350 | AP12: =R12+AL12 -> 10 | AS12: 1 | AT12: TN22SDA894031 | AU12: CDT | AV12: AJITH KUMAR.K | AW12: A | AX12: A | AY12: 33 | AZ12: A | BA12: A | BB12: A | BC12: 36 | BD12: 39 | BE12: =COUNT(AW12:BD12) -> 3 | BF12: =BE12*2 -> 6 | BG12: =BE12/8*100 -> 37.5 | BH12: =BE12*50 -> 150 | BJ12: =IF(BG12<=40,0,IF(BG12<=60,5,IF(BG12>=61,10))) -> 0 | BL12: =AN12+BH12 -> 500 | BN12: =AP12+BJ12 -> 10 | BQ12: 1 | BR12: TN22SDA894031 | BS12: CDT | BT12: AJITH KUMAR.K | BU12: 42 | BV12: 45 | BW12: 48 | BX12: 20 | BY12: =COUNT(BU12:BX12) -> 4 | BZ12: =BY12*2 -> 8 | CA12: =BY12/4*100 -> 100 | CB12: =BY12*50 -> 200 | CD12: =IF(CA12<=40,0,IF(CA12<=60,5,IF(CA12>=61,10))) -> 10 | CF12: =BL12 -> 500 | CK12: 1 | CW12: =COUNT(CO12:CV12) -> 0 | CX12: =CW12*2 -> 0 | CY12: =CW12/5*100 -> 0 | CZ12: =CW12*50 -> 0 | DB12: =IF(CY12<=40,0,IF(CY12<=60,5,IF(CY12>=61,10))) -> 0 | DD12: =CF12+CZ12 -> 500 | DF12: =CH12+DB12 -> 0 | DI12: 1 | DU12: =COUNT(DM12:DT12) -> 0 | DV12: =DU12*2 -> 0 | DW12: =DU12/6*100 -> 0 | DX12: =DU12*50 -> 0 | DZ12: =IF(DW12<=40,0,IF(DW12<=60,5,IF(DW12>=61,10))) -> 0 | EB12: =DD12+DX12 -> 500 | ED12: =DF12+DZ12 -> 0 | EG12: 1 | EH12: TN20SDA894031 | EI12: CDT | EJ12: AVINASH V | FA12: =COUNT(EK12:ER12) -> 0 | FB12: =FA12*2 -> 0 | FC12: =FA12/4*100 -> 0 | FD12: =FA12*50 -> 0 | FF12: =IF(FC12<=40,0,IF(FC12<=60,5,IF(FC12>=61,10))) -> 0 | FH12: =EB12+FD12 -> 500 | FJ12: =ED12+FF12 -> 0 | FN12: =EN12/3 -> 0 | FO12: =FN12/35*100 -> 0
A13: 2 | B13: TN22SDA894032 | C13: CDT | D13: ARJUN.S | E13: A | F13: 3 | G13: A | H13: A | I13: =COUNT(E13:H13) -> 1 | J13: =I13*2 -> 2 | K13: =I13/4*100 -> 25 | L13: =I13*50 -> 50 | N13: =IF(K13<=40,0,IF(K13<=60,5,IF(K13>=61,10))) -> 0 | P13: =L13 -> 50 | R13: =N13 -> 0 | U13: 2 | V13: TN22SDA894032 | W13: CDT | X13: ARJUN.S | Y13: A | Z13: 12 | AA13: 15 | AB13: 18 | AC13: A | AD13: 21 | AE13: 24 | AF13: 27 | AG13: =COUNT(Y13:AF13) -> 6 | AH13: =AG13*2 -> 12 | AI13: =AG13/8*100 -> 75 | AJ13: =AG13*50 -> 300 | AL13: =IF(AI13<=40,0,IF(AI13<=60,5,IF(AI13>=61,10))) -> 10 | AN13: =P13+AJ13 -> 350 | AP13: =R13+AL13 -> 10 | AS13: 2 | AT13: TN22SDA894032 | AU13: CDT | AV13: ARJUN.S | AW13: A | AX13: A | AY13: 30 | AZ13: A | BA13: A | BB13: 33 | BC13: 36 | BD13: A | BE13: =COUNT(AW13:BD13) -> 3 | BF13: =BE13*2 -> 6 | BG13: =BE13/8*100 -> 37.5 | BH13: =BE13*50 -> 150 | BJ13: =IF(BG13<=40,0,IF(BG13<=60,5,IF(BG13>=61,10))) -> 0 | BL13: =AN13+BH13 -> 500 | BN13: =AP13+BJ13 -> 10 | BQ13: 2 | BR13: TN22SDA894032 | BS13: CDT | BT13: ARJUN.S | BU13: A | BV13: 39 | BW13: 42 | BX13: A | BY13: =COUNT(BU13:BX13) -> 2 | BZ13: =BY13*2 -> 4 | CA13: =BY13/4*100 -> 50 | CB13: =BY13*50 -> 100 | CD13: =IF(CA13<=40,0,IF(CA13<=60,5,IF(CA13>=61,10))) -> 5 | CF13: =BL13 -> 500 | CK13: 2 | CW13: =COUNT(CO13:CV13) -> 0 | CX13: =CW13*2 -> 0 | CY13: =CW13/5*100 -> 0 | CZ13: =CW13*50 -> 0 | DB13: =IF(CY13<=40,0,IF(CY13<=60,5,IF(CY13>=61,10))) -> 0 | DD13: =CF13+CZ13 -> 500 | DF13: =CH13+DB13 -> 0 | DI13: 2 | DU13: =COUNT(DM13:DT13) -> 0 | DV13: =DU13*2 -> 0 | DW13: =DU13/6*100 -> 0 | DX13: =DU13*50 -> 0 | DZ13: =IF(DW13<=40,0,IF(DW13<=60,5,IF(DW13>=61,10))) -> 0 | EB13: =DD13+DX13 -> 500 | ED13: =DF13+DZ13 -> 0 | EG13: 2 | EH13: TN20SDA894032 | EI13: CDT | EJ13: BHARATH. C | FA13: =COUNT(EK13:ER13) -> 0 | FB13: =FA13*2 -> 0 | FC13: =FA13/4*100 -> 0 | FD13: =FA13*50 -> 0 | FF13: =IF(FC13<=40,0,IF(FC13<=60,5,IF(FC13>=61,10))) -> 0 | FH13: =EB13+FD13 -> 500 | FJ13: =ED13+FF13 -> 0 | FN13: =EN13/3 -> 0 | FO13: =FN13/35*100 -> 0
A14: 3 | B14: TN22SDA894033 | C14: CDT | D14: ARJUNAN.S | E14: A | F14: A | G14: A | H14: A | I14: =COUNT(E14:H14) -> 0 | J14: =I14*2 -> 0 | K14: =I14/4*100 -> 0 | L14: =I14*50 -> 0 | N14: =IF(K14<=40,0,IF(K14<=60,5,IF(K14>=61,10))) -> 0 | P14: =L14 -> 0 | R14: =N14 -> 0 | U14: 3 | V14: TN22SDA894033 | W14: CDT | X14: ARJUNAN.S | Y14: 3 | Z14: 6 | AA14: 9 | AB14: 12 | AC14: 15 | AD14: 18 | AE14: 21 | AF14: 24 | AG14: =COUNT(Y14:AF14) -> 8 | AH14: =AG14*2 -> 16 | AI14: =AG14/8*100 -> 100 | AJ14: =AG14*50 -> 400 | AL14: =IF(AI14<=40,0,IF(AI14<=60,5,IF(AI14>=61,10))) -> 10 | AN14: =P14+AJ14 -> 400 | AP14: =R14+AL14 -> 10 | AS14: 3 | AT14: TN22SDA894033 | AU14: CDT | AV14: ARJUNAN.S | AW14: 27 | AX14: 30 | AY14: 33 | AZ14: 36 | BA14: A | BB14: 39 | BC14: A | BD14: 42 | BE14: =COUNT(AW14:BD14) -> 6 | BF14: =BE14*2 -> 12 | BG14: =BE14/8*100 -> 75 | BH14: =BE14*50 -> 300 | BJ14: =IF(BG14<=40,0,IF(BG14<=60,5,IF(BG14>=61,10))) -> 10 | BL14: =AN14+BH14 -> 700 | BN14: =AP14+BJ14 -> 20 | BQ14: 3 | BR14: TN22SDA894033 | BS14: CDT | BT14: ARJUNAN.S | BU14: 45 | BV14: 48 | BW14: 51 | BX14: A | BY14: =COUNT(BU14:BX14) -> 3 | BZ14: =BY14*2 -> 6 | CA14: =BY14/4*100 -> 75 | CB14: =BY14*50 -> 150 | CD14: =IF(CA14<=40,0,IF(CA14<=60,5,IF(CA14>=61,10))) -> 10 | CF14: =BL14 -> 700 | CK14: 3 | CW14: =COUNT(CO14:CV14) -> 0 | CX14: =CW14*2 -> 0 | CY14: =CW14/5*100 -> 0 | CZ14: =CW14*50 -> 0 | DB14: =IF(CY14<=40,0,IF(CY14<=60,5,IF(CY14>=61,10))) -> 0 | DD14: =CF14+CZ14 -> 700 | DF14: =CH14+DB14 -> 0 | DI14: 3 | DU14: =COUNT(DM14:DT14) -> 0 | DV14: =DU14*2 -> 0 | DW14: =DU14/6*100 -> 0 | DX14: =DU14*50 -> 0 | DZ14: =IF(DW14<=40,0,IF(DW14<=60,5,IF(DW14>=61,10))) -> 0 | EB14: =DD14+DX14 -> 700 | ED14: =DF14+DZ14 -> 0 | EG14: 3 | EH14: TN20SDA894033 | EI14: CDT | EJ14: DHILIP.K | FA14: =COUNT(EK14:ER14) -> 0 | FB14: =FA14*2 -> 0 | FC14: =FA14/4*100 -> 0 | FD14: =FA14*50 -> 0 | FF14: =IF(FC14<=40,0,IF(FC14<=60,5,IF(FC14>=61,10))) -> 0 | FH14: =EB14+FD14 -> 700 | FJ14: =ED14+FF14 -> 0 | FN14: =EN14/3 -> 0 | FO14: =FN14/35*100 -> 0
A15: 4 | B15: TN22SDA894034 | C15: CDT | D15: BALA ABISHEK.S | E15: A | F15: 3 | G15: A | H15: A | I15: =COUNT(E15:H15) -> 1 | J15: =I15*2 -> 2 | K15: =I15/4*100 -> 25 | L15: =I15*50 -> 50 | N15: =IF(K15<=40,0,IF(K15<=60,5,IF(K15>=61,10))) -> 0 | P15: =L15 -> 50 | R15: =N15 -> 0 | U15: 4 | V15: TN22SDA894034 | W15: CDT | X15: BALA ABISHEK.S | Y15: 15 | Z15: A | AA15: 18 | AB15: 21 | AC15: A | AD15: 24 | AE15: 27 | AF15: 30 | AG15: =COUNT(Y15:AF15) -> 6 | AH15: =AG15*2 -> 12 | AI15: =AG15/8*100 -> 75 | AJ15: =AG15*50 -> 300 | AL15: =IF(AI15<=40,0,IF(AI15<=60,5,IF(AI15>=61,10))) -> 10 | AN15: =P15+AJ15 -> 350 | AP15: =R15+AL15 -> 10 | AS15: 4 | AT15: TN22SDA894034 | AU15: CDT | AV15: BALA ABISHEK.S | AW15: A | AX15: 33 | AY15: A | AZ15: 36 | BA15: 39 | BB15: A | BC15: 41 | BD15: A | BE15: =COUNT(AW15:BD15) -> 4 | BF15: =BE15*2 -> 8 | BG15: =BE15/8*100 -> 50 | BH15: =BE15*50 -> 200 | BJ15: =IF(BG15<=40,0,IF(BG15<=60,5,IF(BG15>=61,10))) -> 5 | BL15: =AN15+BH15 -> 550 | BN15: =AP15+BJ15 -> 15 | BQ15: 4 | BR15: TN22SDA894034 | BS15: CDT | BT15: BALA ABISHEK.S | BU15: 42 | BV15: 45 | BW15: A | BX15: 48 | BY15: =COUNT(BU15:BX15) -> 3 | BZ15: =BY15*2 -> 6 | CA15: =BY15/4*100 -> 75 | CB15: =BY15*50 -> 150 | CD15: =IF(CA15<=40,0,IF(CA15<=60,5,IF(CA15>=61,10))) -> 10 | CF15: =BL15 -> 550 | CK15: 4 | CW15: =COUNT(CO15:CV15) -> 0 | CX15: =CW15*2 -> 0 | CY15: =CW15/5*100 -> 0 | CZ15: =CW15*50 -> 0 | DB15: =IF(CY15<=40,0,IF(CY15<=60,5,IF(CY15>=61,10))) -> 0 | DD15: =CF15+CZ15 -> 550 | DF15: =CH15+DB15 -> 0 | DI15: 4 | DU15: =COUNT(DM15:DT15) -> 0 | DV15: =DU15*2 -> 0 | DW15: =DU15/6*100 -> 0 | DX15: =DU15*50 -> 0 | DZ15: =IF(DW15<=40,0,IF(DW15<=60,5,IF(DW15>=61,10))) -> 0 | EB15: =DD15+DX15 -> 550 | ED15: =DF15+DZ15 -> 0 | EG15: 4 | EH15: TN20SDA894034 | EI15: CDT | EJ15: GOKUL T | FA15: =COUNT(EK15:ER15) -> 0 | FB15: =FA15*2 -> 0 | FC15: =FA15/4*100 -> 0 | FD15: =FA15*50 -> 0 | FF15: =IF(FC15<=40,0,IF(FC15<=60,5,IF(FC15>=61,10))) -> 0 | FH15: =EB15+FD15 -> 550 | FJ15: =ED15+FF15 -> 0 | FN15: =EN15/3 -> 0 | FO15: =FN15/35*100 -> 0
A16: 5 | B16: TN22SDA894035 | C16: CDT | D16: DHARUN.R.S | E16: 3 | F16: 6 | G16: 9 | H16: 12 | I16: =COUNT(E16:H16) -> 4 | J16: =I16*2 -> 8 | K16: =I16/4*100 -> 100 | L16: =I16*50 -> 200 | N16: =IF(K16<=40,0,IF(K16<=60,5,IF(K16>=61,10))) -> 10 | P16: =L16 -> 200 | R16: =N16 -> 10 | U16: 5 | V16: TN22SDA894035 | W16: CDT | X16: DHARUN.R.S | Y16: 15 | Z16: A | AA16: 18 | AB16: 21 | AC16: 24 | AD16: 27 | AE16: 30 | AF16: A | AG16: =COUNT(Y16:AF16) -> 6 | AH16: =AG16*2 -> 12 | AI16: =AG16/8*100 -> 75 | AJ16: =AG16*50 -> 300 | AL16: =IF(AI16<=40,0,IF(AI16<=60,5,IF(AI16>=61,10))) -> 10 | AN16: =P16+AJ16 -> 500 | AP16: =R16+AL16 -> 20 | AS16: 5 | AT16: TN22SDA894035 | AU16: CDT | AV16: DHARUN.R.S | AW16: 33 | AX16: 36 | AY16: 39 | AZ16: 41 | BA16: 45 | BB16: 48 | BC16: A | BD16: 51 | BE16: =COUNT(AW16:BD16) -> 7 | BF16: =BE16*2 -> 14 | BG16: =BE16/8*100 -> 87.5 | BH16: =BE16*50 -> 350 | BJ16: =IF(BG16<=40,0,IF(BG16<=60,5,IF(BG16>=61,10))) -> 10 | BL16: =AN16+BH16 -> 850 | BN16: =AP16+BJ16 -> 30 | BQ16: 5 | BR16: TN22SDA894035 | BS16: CDT | BT16: DHARUN.R.S | BU16: A | BV16: 54 | BW16: 57 | BX16: 60 | BY16: =COUNT(BU16:BX16) -> 3 | BZ16: =BY16*2 -> 6 | CA16: =BY16/4*100 -> 75 | CB16: =BY16*50 -> 150 | CD16: =IF(CA16<=40,0,IF(CA16<=60,5,IF(CA16>=61,10))) -> 10 | CF16: =BL16 -> 850 | CK16: 5 | CW16: =COUNT(CO16:CV16) -> 0 | CX16: =CW16*2 -> 0 | CY16: =CW16/5*100 -> 0 | CZ16: =CW16*50 -> 0 | DB16: =IF(CY16<=40,0,IF(CY16<=60,5,IF(CY16>=61,10))) -> 0 | DD16: =CF16+CZ16 -> 850 | DF16: =CH16+DB16 -> 0 | DI16: 5 | DU16: =COUNT(DM16:DT16) -> 0 | DV16: =DU16*2 -> 0 | DW16: =DU16/6*100 -> 0 | DX16: =DU16*50 -> 0 | DZ16: =IF(DW16<=40,0,IF(DW16<=60,5,IF(DW16>=61,10))) -> 0 | EB16: =DD16+DX16 -> 850 | ED16: =DF16+DZ16 -> 0 | EG16: 5 | EH16: TN20SDA894035 | EI16: CDT | EJ16: HARI HARAN.E | FA16: =COUNT(EK16:ER16) -> 0 | FB16: =FA16*2 -> 0 | FC16: =FA16/4*100 -> 0 | FD16: =FA16*50 -> 0 | FF16: =IF(FC16<=40,0,IF(FC16<=60,5,IF(FC16>=61,10))) -> 0 | FH16: =EB16+FD16 -> 850 | FJ16: =ED16+FF16 -> 0 | FN16: =EN16/3 -> 0 | FO16: =FN16/35*100 -> 0
A17: 6 | B17: TN22SDA894036 | C17: CDT | D17: JAYA RAMAN.T | E17: 3 | F17: 6 | G17: 9 | H17: 12 | I17: =COUNT(E17:H17) -> 4 | J17: =I17*2 -> 8 | K17: =I17/4*100 -> 100 | L17: =I17*50 -> 200 | N17: =IF(K17<=40,0,IF(K17<=60,5,IF(K17>=61,10))) -> 10 | P17: =L17 -> 200 | R17: =N17 -> 10 | U17: 6 | V17: TN22SDA894036 | W17: CDT | X17: JAYA RAMAN.T | Y17: 15 | Z17: 18 | AA17: A | AB17: 21 | AC17: 24 | AD17: 27 | AE17: 30 | AF17: A | AG17: =COUNT(Y17:AF17) -> 6 | AH17: =AG17*2 -> 12 | AI17: =AG17/8*100 -> 75 | AJ17: =AG17*50 -> 300 | AL17: =IF(AI17<=40,0,IF(AI17<=60,5,IF(AI17>=61,10))) -> 10 | AN17: =P17+AJ17 -> 500 | AP17: =R17+AL17 -> 20 | AS17: 6 | AT17: TN22SDA894036 | AU17: CDT | AV17: JAYA RAMAN.T | AW17: 33 | AX17: 36 | AY17: A | AZ17: 39 | BA17: 42 | BB17: 45 | BC17: A | BD17: 48 | BE17: =COUNT(AW17:BD17) -> 6 | BF17: =BE17*2 -> 12 | BG17: =BE17/8*100 -> 75 | BH17: =BE17*50 -> 300 | BJ17: =IF(BG17<=40,0,IF(BG17<=60,5,IF(BG17>=61,10))) -> 10 | BL17: =AN17+BH17 -> 800 | BN17: =AP17+BJ17 -> 30 | BQ17: 6 | BR17: TN22SDA894036 | BS17: CDT | BT17: JAYA RAMAN.T | BU17: 51 | BV17: A | BW17: 54 | BX17: A | BY17: =COUNT(BU17:BX17) -> 2 | BZ17: =BY17*2 -> 4 | CA17: =BY17/4*100 -> 50 | CB17: =BY17*50 -> 100 | CD17: =IF(CA17<=40,0,IF(CA17<=60,5,IF(CA17>=61,10))) -> 5 | CF17: =BL17 -> 800 | CK17: 6 | CW17: =COUNT(CO17:CV17) -> 0 | CX17: =CW17*2 -> 0 | CY17: =CW17/5*100 -> 0 | CZ17: =CW17*50 -> 0 | DB17: =IF(CY17<=40,0,IF(CY17<=60,5,IF(CY17>=61,10))) -> 0 | DD17: =CF17+CZ17 -> 800 | DF17: =CH17+DB17 -> 0 | DI17: 6 | DU17: =COUNT(DM17:DT17) -> 0 | DV17: =DU17*2 -> 0 | DW17: =DU17/6*100 -> 0 | DX17: =DU17*50 -> 0 | DZ17: =IF(DW17<=40,0,IF(DW17<=60,5,IF(DW17>=61,10))) -> 0 | EB17: =DD17+DX17 -> 800 | ED17: =DF17+DZ17 -> 0 | EG17: 6 | EH17: TN20SDA894036 | EI17: CDT | EJ17: JEGANADHAN.K | FA17: =COUNT(EK17:ER17) -> 0 | FB17: =FA17*2 -> 0 | FC17: =FA17/4*100 -> 0 | FD17: =FA17*50 -> 0 | FF17: =IF(FC17<=40,0,IF(FC17<=60,5,IF(FC17>=61,10))) -> 0 | FH17: =EB17+FD17 -> 800 | FJ17: =ED17+FF17 -> 0 | FN17: =EN17/3 -> 0 | FO17: =FN17/35*100 -> 0
A18: 7 | B18: TN22SDA894037 | C18: CDT | D18: LAKSHMANAN.R | E18: 3 | F18: 6 | G18: 9 | H18: 12 | I18: =COUNT(E18:H18) -> 4 | J18: =I18*2 -> 8 | K18: =I18/4*100 -> 100 | L18: =I18*50 -> 200 | N18: =IF(K18<=40,0,IF(K18<=60,5,IF(K18>=61,10))) -> 10 | P18: =L18 -> 200 | R18: =N18 -> 10 | U18: 7 | V18: TN22SDA894037 | W18: CDT | X18: LAKSHMANAN.R | Y18: 15 | Z18: 18 | AA18: 21 | AB18: 24 | AC18: 27 | AD18: 30 | AE18: A | AF18: A | AG18: =COUNT(Y18:AF18) -> 6 | AH18: =AG18*2 -> 12 | AI18: =AG18/8*100 -> 75 | AJ18: =AG18*50 -> 300 | AL18: =IF(AI18<=40,0,IF(AI18<=60,5,IF(AI18>=61,10))) -> 10 | AN18: =P18+AJ18 -> 500 | AP18: =R18+AL18 -> 20 | AS18: 7 | AT18: TN22SDA894037 | AU18: CDT | AV18: LAKSHMANAN.R | AW18: 33 | AX18: 36 | AY18: A | AZ18: 39 | BA18: A | BB18: 42 | BC18: 45 | BD18: 48 | BE18: =COUNT(AW18:BD18) -> 6 | BF18: =BE18*2 -> 12 | BG18: =BE18/8*100 -> 75 | BH18: =BE18*50 -> 300 | BJ18: =IF(BG18<=40,0,IF(BG18<=60,5,IF(BG18>=61,10))) -> 10 | BL18: =AN18+BH18 -> 800 | BN18: =AP18+BJ18 -> 30 | BQ18: 7 | BR18: TN22SDA894037 | BS18: CDT | BT18: LAKSHMANAN.R | BU18: A | BV18: 51 | BW18: A | BX18: 54 | BY18: =COUNT(BU18:BX18) -> 2 | BZ18: =BY18*2 -> 4 | CA18: =BY18/4*100 -> 50 | CB18: =BY18*50 -> 100 | CD18: =IF(CA18<=40,0,IF(CA18<=60,5,IF(CA18>=61,10))) -> 5 | CF18: =BL18 -> 800 | CK18: 7 | CW18: =COUNT(CO18:CV18) -> 0 | CX18: =CW18*2 -> 0 | CY18: =CW18/5*100 -> 0 | CZ18: =CW18*50 -> 0 | DB18: =IF(CY18<=40,0,IF(CY18<=60,5,IF(CY18>=61,10))) -> 0 | DD18: =CF18+CZ18 -> 800 | DF18: =CH18+DB18 -> 0 | DI18: 7 | DU18: =COUNT(DM18:DT18) -> 0 | DV18: =DU18*2 -> 0 | DW18: =DU18/6*100 -> 0 | DX18: =DU18*50 -> 0 | DZ18: =IF(DW18<=40,0,IF(DW18<=60,5,IF(DW18>=61,10))) -> 0 | EB18: =DD18+DX18 -> 800 | ED18: =DF18+DZ18 -> 0 | EG18: 7 | EH18: TN20SDA894037 | EI18: CSM | EJ18: KAMAL RAJ.S | FA18: =COUNT(EK18:ER18) -> 0 | FB18: =FA18*2 -> 0 | FC18: =FA18/4*100 -> 0 | FD18: =FA18*50 -> 0 | FF18: =IF(FC18<=40,0,IF(FC18<=60,5,IF(FC18>=61,10))) -> 0 | FH18: =EB18+FD18 -> 800 | FJ18: =ED18+FF18 -> 0 | FN18: =EN18/3 -> 0 | FO18: =FN18/35*100 -> 0
A19: 8 | B19: TN22SDA894038 | C19: CDT | D19: MADHAVA BRIGHTLY.A | E19: 3 | F19: A | G19: A | H19: A | I19: =COUNT(E19:H19) -> 1 | J19: =I19*2 -> 2 | K19: =I19/4*100 -> 25 | L19: =I19*50 -> 50 | N19: =IF(K19<=40,0,IF(K19<=60,5,IF(K19>=61,10))) -> 0 | P19: =L19 -> 50 | R19: =N19 -> 0 | U19: 8 | V19: TN22SDA894038 | W19: CDT | X19: MADHAVA BRIGHTLY.A | Y19: 9 | Z19: 12 | AA19: A | AB19: A | AC19: 15 | AD19: A | AE19: A | AF19: 18 | AG19: =COUNT(Y19:AF19) -> 4 | AH19: =AG19*2 -> 8 | AI19: =AG19/8*100 -> 50 | AJ19: =AG19*50 -> 200 | AL19: =IF(AI19<=40,0,IF(AI19<=60,5,IF(AI19>=61,10))) -> 5 | AN19: =P19+AJ19 -> 250 | AP19: =R19+AL19 -> 5 | AS19: 8 | AT19: TN22SDA894038 | AU19: CDT | AV19: MADHAVA BRIGHTLY.A | AW19: A | AX19: A | AY19: A | AZ19: 21 | BA19: 24 | BB19: A | BC19: 27 | BD19: A | BE19: =COUNT(AW19:BD19) -> 3 | BF19: =BE19*2 -> 6 | BG19: =BE19/8*100 -> 37.5 | BH19: =BE19*50 -> 150 | BJ19: =IF(BG19<=40,0,IF(BG19<=60,5,IF(BG19>=61,10))) -> 0 | BL19: =AN19+BH19 -> 400 | BN19: =AP19+BJ19 -> 5 | BQ19: 8 | BR19: TN22SDA894038 | BS19: CDT | BT19: MADHAVA BRIGHTLY.A | BU19: 30 | BV19: A | BW19: 33 | BX19: A | BY19: =COUNT(BU19:BX19) -> 2 | BZ19: =BY19*2 -> 4 | CA19: =BY19/4*100 -> 50 | CB19: =BY19*50 -> 100 | CD19: =IF(CA19<=40,0,IF(CA19<=60,5,IF(CA19>=61,10))) -> 5 | CF19: =BL19 -> 400 | CK19: 8 | CW19: =COUNT(CO19:CV19) -> 0 | CX19: =CW19*2 -> 0 | CY19: =CW19/5*100 -> 0 | CZ19: =CW19*50 -> 0 | DB19: =IF(CY19<=40,0,IF(CY19<=60,5,IF(CY19>=61,10))) -> 0 | DD19: =CF19+CZ19 -> 400 | DF19: =CH19+DB19 -> 0 | DI19: 8 | DU19: =COUNT(DM19:DT19) -> 0 | DV19: =DU19*2 -> 0 | DW19: =DU19/6*100 -> 0 | DX19: =DU19*50 -> 0 | DZ19: =IF(DW19<=40,0,IF(DW19<=60,5,IF(DW19>=61,10))) -> 0 | EB19: =DD19+DX19 -> 400 | ED19: =DF19+DZ19 -> 0 | EG19: 8 | EH19: TN20SDA894038 | EI19: CUO | EJ19: KARTHICK P | FA19: =COUNT(EK19:ER19) -> 0 | FB19: =FA19*2 -> 0 | FC19: =FA19/4*100 -> 0 | FD19: =FA19*50 -> 0 | FF19: =IF(FC19<=40,0,IF(FC19<=60,5,IF(FC19>=61,10))) -> 0 | FH19: =EB19+FD19 -> 400 | FJ19: =ED19+FF19 -> 0 | FN19: =EN19/3 -> 0 | FO19: =FN19/35*100 -> 0
A20: 9 | B20: TN22SDA894039 | C20: CDT | D20: MANMOHAN.M.S | E20: 3 | F20: 6 | G20: 9 | H20: 12 | I20: =COUNT(E20:H20) -> 4 | J20: =I20*2 -> 8 | K20: =I20/4*100 -> 100 | L20: =I20*50 -> 200 | N20: =IF(K20<=40,0,IF(K20<=60,5,IF(K20>=61,10))) -> 10 | P20: =L20 -> 200 | R20: =N20 -> 10 | U20: 9 | V20: TN22SDA894039 | W20: CDT | X20: MANMOHAN.M.S | Y20: 9 | Z20: 12 | AA20: 15 | AB20: 18 | AC20: 21 | AD20: 24 | AE20: 27 | AF20: 30 | AG20: =COUNT(Y20:AF20) -> 8 | AH20: =AG20*2 -> 16 | AI20: =AG20/8*100 -> 100 | AJ20: =AG20*50 -> 400 | AL20: =IF(AI20<=40,0,IF(AI20<=60,5,IF(AI20>=61,10))) -> 10 | AN20: =P20+AJ20 -> 600 | AP20: =R20+AL20 -> 20 | AS20: 9 | AT20: TN22SDA894039 | AU20: CDT | AV20: MANMOHAN.M.S | AW20: A | AX20: A | AY20: 33 | AZ20: 36 | BA20: 39 | BB20: 42 | BC20: 45 | BD20: 48 | BE20: =COUNT(AW20:BD20) -> 6 | BF20: =BE20*2 -> 12 | BG20: =BE20/8*100 -> 75 | BH20: =BE20*50 -> 300 | BJ20: =IF(BG20<=40,0,IF(BG20<=60,5,IF(BG20>=61,10))) -> 10 | BL20: =AN20+BH20 -> 900 | BN20: =AP20+BJ20 -> 30 | BQ20: 9 | BR20: TN22SDA894039 | BS20: CDT | BT20: MANMOHAN.M.S | BU20: A | BV20: 51 | BW20: A | BX20: 54 | BY20: =COUNT(BU20:BX20) -> 2 | BZ20: =BY20*2 -> 4 | CA20: =BY20/4*100 -> 50 | CB20: =BY20*50 -> 100 | CD20: =IF(CA20<=40,0,IF(CA20<=60,5,IF(CA20>=61,10))) -> 5 | CF20: =BL20 -> 900 | CK20: 9 | CW20: =COUNT(CO20:CV20) -> 0 | CX20: =CW20*2 -> 0 | CY20: =CW20/5*100 -> 0 | CZ20: =CW20*50 -> 0 | DB20: =IF(CY20<=40,0,IF(CY20<=60,5,IF(CY20>=61,10))) -> 0 | DD20: =CF20+CZ20 -> 900 | DF20: =CH20+DB20 -> 0 | DI20: 9 | DU20: =COUNT(DM20:DT20) -> 0 | DV20: =DU20*2 -> 0 | DW20: =DU20/6*100 -> 0 | DX20: =DU20*50 -> 0 | DZ20: =IF(DW20<=40,0,IF(DW20<=60,5,IF(DW20>=61,10))) -> 0 | EB20: =DD20+DX20 -> 900 | ED20: =DF20+DZ20 -> 0 | EG20: 9 | EH20: TN20SDA894039 | EI20: SGT | EJ20: KEERTHESWARAN.S | FA20: =COUNT(EK20:ER20) -> 0 | FB20: =FA20*2 -> 0 | FC20: =FA20/4*100 -> 0 | FD20: =FA20*50 -> 0 | FF20: =IF(FC20<=40,0,IF(FC20<=60,5,IF(FC20>=61,10))) -> 0 | FH20: =EB20+FD20 -> 900 | FJ20: =ED20+FF20 -> 0 | FN20: =EN20/3 -> 0 | FO20: =FN20/35*100 -> 0
A21: 10 | B21: TN22SDA894040 | C21: CDT | D21: PRANESH.S | E21: 3 | F21: 6 | G21: 9 | H21: 12 | I21: =COUNT(E21:H21) -> 4 | J21: =I21*2 -> 8 | K21: =I21/4*100 -> 100 | L21: =I21*50 -> 200 | N21: =IF(K21<=40,0,IF(K21<=60,5,IF(K21>=61,10))) -> 10 | P21: =L21 -> 200 | R21: =N21 -> 10 | U21: 10 | V21: TN22SDA894040 | W21: CDT | X21: PRANESH.S | Y21: 15 | Z21: A | AA21: A | AB21: A | AC21: A | AD21: A | AE21: A | AF21: 18 | AG21: =COUNT(Y21:AF21) -> 2 | AH21: =AG21*2 -> 4 | AI21: =AG21/8*100 -> 25 | AJ21: =AG21*50 -> 100 | AL21: =IF(AI21<=40,0,IF(AI21<=60,5,IF(AI21>=61,10))) -> 0 | AN21: =P21+AJ21 -> 300 | AP21: =R21+AL21 -> 10 | AS21: 10 | AT21: TN22SDA894040 | AU21: CDT | AV21: PRANESH.S | AW21: 21 | AX21: 24 | AY21: A | AZ21: A | BA21: 27 | BB21: 30 | BC21: A | BD21: 33 | BE21: =COUNT(AW21:BD21) -> 5 | BF21: =BE21*2 -> 10 | BG21: =BE21/8*100 -> 62.5 | BH21: =BE21*50 -> 250 | BJ21: =IF(BG21<=40,0,IF(BG21<=60,5,IF(BG21>=61,10))) -> 10 | BL21: =AN21+BH21 -> 550 | BN21: =AP21+BJ21 -> 20 | BQ21: 10 | BR21: TN22SDA894040 | BS21: CDT | BT21: PRANESH.S | BU21: A | BV21: A | BW21: 36 | BX21: A | BY21: =COUNT(BU21:BX21) -> 1 | BZ21: =BY21*2 -> 2 | CA21: =BY21/4*100 -> 25 | CB21: =BY21*50 -> 50 | CD21: =IF(CA21<=40,0,IF(CA21<=60,5,IF(CA21>=61,10))) -> 0 | CF21: =BL21 -> 550 | CK21: 10 | CW21: =COUNT(CO21:CV21) -> 0 | CX21: =CW21*2 -> 0 | CY21: =CW21/5*100 -> 0 | CZ21: =CW21*50 -> 0 | DB21: =IF(CY21<=40,0,IF(CY21<=60,5,IF(CY21>=61,10))) -> 0 | DD21: =CF21+CZ21 -> 550 | DF21: =CH21+DB21 -> 0 | DI21: 10 | DU21: =COUNT(DM21:DT21) -> 0 | DV21: =DU21*2 -> 0 | DW21: =DU21/6*100 -> 0 | DX21: =DU21*50 -> 0 | DZ21: =IF(DW21<=40,0,IF(DW21<=60,5,IF(DW21>=61,10))) -> 0 | EB21: =DD21+DX21 -> 550 | ED21: =DF21+DZ21 -> 0 | EG21: 10 | EH21: TN20SDA894040 | EI21: CDT | EJ21: MANI KANADA PRABHU S | FA21: =COUNT(EK21:ER21) -> 0 | FB21: =FA21*2 -> 0 | FC21: =FA21/4*100 -> 0 | FD21: =FA21*50 -> 0 | FF21: =IF(FC21<=40,0,IF(FC21<=60,5,IF(FC21>=61,10))) -> 0 | FH21: =EB21+FD21 -> 550 | FJ21: =ED21+FF21 -> 0 | FN21: =EN21/3 -> 0 | FO21: =FN21/35*100 -> 0
A22: 11 | B22: TN22SDA894041 | C22: CDT | D22: PRASANTH.A | E22: 3 | F22: A | G22: 6 | H22: A | I22: =COUNT(E22:H22) -> 2 | J22: =I22*2 -> 4 | K22: =I22/4*100 -> 50 | L22: =I22*50 -> 100 | N22: =IF(K22<=40,0,IF(K22<=60,5,IF(K22>=61,10))) -> 5 | P22: =L22 -> 100 | R22: =N22 -> 5 | U22: 11 | V22: TN22SDA894041 | W22: CDT | X22: PRASANTH.A | Y22: A | Z22: A | AA22: 15 | AB22: 18 | AC22: 21 | AD22: 24 | AE22: 27 | AF22: 30 | AG22: =COUNT(Y22:AF22) -> 6 | AH22: =AG22*2 -> 12 | AI22: =AG22/8*100 -> 75 | AJ22: =AG22*50 -> 300 | AL22: =IF(AI22<=40,0,IF(AI22<=60,5,IF(AI22>=61,10))) -> 10 | AN22: =P22+AJ22 -> 400 | AP22: =R22+AL22 -> 15 | AS22: 11 | AT22: TN22SDA894041 | AU22: CDT | AV22: PRASANTH.A | AW22: A | AX22: A | AY22: 33 | AZ22: 36 | BA22: 39 | BB22: 42 | BC22: 45 | BD22: A | BE22: =COUNT(AW22:BD22) -> 5 | BF22: =BE22*2 -> 10 | BG22: =BE22/8*100 -> 62.5 | BH22: =BE22*50 -> 250 | BJ22: =IF(BG22<=40,0,IF(BG22<=60,5,IF(BG22>=61,10))) -> 10 | BL22: =AN22+BH22 -> 650 | BN22: =AP22+BJ22 -> 25 | BQ22: 11 | BR22: TN22SDA894041 | BS22: CDT | BT22: PRASANTH.A | BU22: 48 | BV22: 51 | BW22: A | BX22: 54 | BY22: =COUNT(BU22:BX22) -> 3 | BZ22: =BY22*2 -> 6 | CA22: =BY22/4*100 -> 75 | CB22: =BY22*50 -> 150 | CD22: =IF(CA22<=40,0,IF(CA22<=60,5,IF(CA22>=61,10))) -> 10 | CF22: =BL22 -> 650 | CK22: 11 | CW22: =COUNT(CO22:CV22) -> 0 | CX22: =CW22*2 -> 0 | CY22: =CW22/5*100 -> 0 | CZ22: =CW22*50 -> 0 | DB22: =IF(CY22<=40,0,IF(CY22<=60,5,IF(CY22>=61,10))) -> 0 | DD22: =CF22+CZ22 -> 650 | DF22: =CH22+DB22 -> 0 | DI22: 11 | DU22: =COUNT(DM22:DT22) -> 0 | DV22: =DU22*2 -> 0 | DW22: =DU22/6*100 -> 0 | DX22: =DU22*50 -> 0 | DZ22: =IF(DW22<=40,0,IF(DW22<=60,5,IF(DW22>=61,10))) -> 0 | EB22: =DD22+DX22 -> 650 | ED22: =DF22+DZ22 -> 0 | EG22: 11 | EH22: TN20SDA894041 | EI22: CDT | EJ22: NAVEEN KUMAR.B | FA22: =COUNT(EK22:ER22) -> 0 | FB22: =FA22*2 -> 0 | FC22: =FA22/4*100 -> 0 | FD22: =FA22*50 -> 0 | FF22: =IF(FC22<=40,0,IF(FC22<=60,5,IF(FC22>=61,10))) -> 0 | FH22: =EB22+FD22 -> 650 | FJ22: =ED22+FF22 -> 0 | FN22: =EN22/3 -> 0 | FO22: =FN22/35*100 -> 0
A23: 12 | B23: TN22SDA894042 | C23: CDT | D23: RAGHUL.J | E23: 3 | F23: A | G23: 6 | H23: 9 | I23: =COUNT(E23:H23) -> 3 | J23: =I23*2 -> 6 | K23: =I23/4*100 -> 75 | L23: =I23*50 -> 150 | N23: =IF(K23<=40,0,IF(K23<=60,5,IF(K23>=61,10))) -> 10 | P23: =L23 -> 150 | R23: =N23 -> 10 | U23: 12 | V23: TN22SDA894042 | W23: CDT | X23: RAGHUL.J | Y23: A | Z23: 6 | AA23: A | AB23: A | AC23: 9 | AD23: A | AE23: A | AF23: A | AG23: =COUNT(Y23:AF23) -> 2 | AH23: =AG23*2 -> 4 | AI23: =AG23/8*100 -> 25 | AJ23: =AG23*50 -> 100 | AL23: =IF(AI23<=40,0,IF(AI23<=60,5,IF(AI23>=61,10))) -> 0 | AN23: =P23+AJ23 -> 250 | AP23: =R23+AL23 -> 10 | AS23: 12 | AT23: TN22SDA894042 | AU23: CDT | AV23: RAGHUL.J | AW23: 12 | AX23: 15 | AY23: A | AZ23: 18 | BA23: A | BB23: A | BC23: 21 | BD23: 24 | BE23: =COUNT(AW23:BD23) -> 5 | BF23: =BE23*2 -> 10 | BG23: =BE23/8*100 -> 62.5 | BH23: =BE23*50 -> 250 | BJ23: =IF(BG23<=40,0,IF(BG23<=60,5,IF(BG23>=61,10))) -> 10 | BL23: =AN23+BH23 -> 500 | BN23: =AP23+BJ23 -> 20 | BQ23: 12 | BR23: TN22SDA894042 | BS23: CDT | BT23: RAGHUL.J | BU23: A | BV23: 27 | BW23: 30 | BX23: A | BY23: =COUNT(BU23:BX23) -> 2 | BZ23: =BY23*2 -> 4 | CA23: =BY23/4*100 -> 50 | CB23: =BY23*50 -> 100 | CD23: =IF(CA23<=40,0,IF(CA23<=60,5,IF(CA23>=61,10))) -> 5 | CF23: =BL23 -> 500 | CK23: 12 | CW23: =COUNT(CO23:CV23) -> 0 | CX23: =CW23*2 -> 0 | CY23: =CW23/5*100 -> 0 | CZ23: =CW23*50 -> 0 | DB23: =IF(CY23<=40,0,IF(CY23<=60,5,IF(CY23>=61,10))) -> 0 | DD23: =CF23+CZ23 -> 500 | DF23: =CH23+DB23 -> 0 | DI23: 12 | DU23: =COUNT(DM23:DT23) -> 0 | DV23: =DU23*2 -> 0 | DW23: =DU23/6*100 -> 0 | DX23: =DU23*50 -> 0 | DZ23: =IF(DW23<=40,0,IF(DW23<=60,5,IF(DW23>=61,10))) -> 0 | EB23: =DD23+DX23 -> 500 | ED23: =DF23+DZ23 -> 0 | EG23: 12 | EH23: TN20SDA894042 | EI23: CDT | EJ23: RANJITH.V.P | FA23: =COUNT(EK23:ER23) -> 0 | FB23: =FA23*2 -> 0 | FC23: =FA23/4*100 -> 0 | FD23: =FA23*50 -> 0 | FF23: =IF(FC23<=40,0,IF(FC23<=60,5,IF(FC23>=61,10))) -> 0 | FH23: =EB23+FD23 -> 500 | FJ23: =ED23+FF23 -> 0 | FN23: =EN23/3 -> 0 | FO23: =FN23/35*100 -> 0
A24: 13 | B24: TN22SDA894043 | C24: CDT | D24: SANJAY.K | E24: 3 | F24: 6 | G24: 9 | H24: 12 | I24: =COUNT(E24:H24) -> 4 | J24: =I24*2 -> 8 | K24: =I24/4*100 -> 100 | L24: =I24*50 -> 200 | N24: =IF(K24<=40,0,IF(K24<=60,5,IF(K24>=61,10))) -> 10 | P24: =L24 -> 200 | R24: =N24 -> 10 | U24: 13 | V24: TN22SDA894043 | W24: CDT | X24: SANJAY.K | Y24: 12 | Z24: 15 | AA24: 18 | AB24: 21 | AC24: A | AD24: 24 | AE24: 27 | AF24: 30 | AG24: =COUNT(Y24:AF24) -> 7 | AH24: =AG24*2 -> 14 | AI24: =AG24/8*100 -> 87.5 | AJ24: =AG24*50 -> 350 | AL24: =IF(AI24<=40,0,IF(AI24<=60,5,IF(AI24>=61,10))) -> 10 | AN24: =P24+AJ24 -> 550 | AP24: =R24+AL24 -> 20 | AS24: 13 | AT24: TN22SDA894043 | AU24: CDT | AV24: SANJAY.K | AW24: 33 | AX24: 36 | AY24: 39 | AZ24: A | BA24: 42 | BB24: 45 | BC24: 48 | BD24: A | BE24: =COUNT(AW24:BD24) -> 6 | BF24: =BE24*2 -> 12 | BG24: =BE24/8*100 -> 75 | BH24: =BE24*50 -> 300 | BJ24: =IF(BG24<=40,0,IF(BG24<=60,5,IF(BG24>=61,10))) -> 10 | BL24: =AN24+BH24 -> 850 | BN24: =AP24+BJ24 -> 30 | BQ24: 13 | BR24: TN22SDA894043 | BS24: CDT | BT24: SANJAY.K | BU24: 51 | BV24: 54 | BW24: A | BX24: 57 | BY24: =COUNT(BU24:BX24) -> 3 | BZ24: =BY24*2 -> 6 | CA24: =BY24/4*100 -> 75 | CB24: =BY24*50 -> 150 | CD24: =IF(CA24<=40,0,IF(CA24<=60,5,IF(CA24>=61,10))) -> 10 | CF24: =BL24 -> 850 | CK24: 13 | CW24: =COUNT(CO24:CV24) -> 0 | CX24: =CW24*2 -> 0 | CY24: =CW24/5*100 -> 0 | CZ24: =CW24*50 -> 0 | DB24: =IF(CY24<=40,0,IF(CY24<=60,5,IF(CY24>=61,10))) -> 0 | DD24: =CF24+CZ24 -> 850 | DF24: =CH24+DB24 -> 0 | DI24: 13 | DU24: =COUNT(DM24:DT24) -> 0 | DV24: =DU24*2 -> 0 | DW24: =DU24/6*100 -> 0 | DX24: =DU24*50 -> 0 | DZ24: =IF(DW24<=40,0,IF(DW24<=60,5,IF(DW24>=61,10))) -> 0 | EB24: =DD24+DX24 -> 850 | ED24: =DF24+DZ24 -> 0 | EG24: 13 | EH24: TN20SDA894043 | EI24: CDT | EJ24: SIVASANMUGAN G | FA24: =COUNT(EK24:ER24) -> 0 | FB24: =FA24*2 -> 0 | FC24: =FA24/4*100 -> 0 | FD24: =FA24*50 -> 0 | FF24: =IF(FC24<=40,0,IF(FC24<=60,5,IF(FC24>=61,10))) -> 0 | FH24: =EB24+FD24 -> 850 | FJ24: =ED24+FF24 -> 0 | FN24: =EN24/3 -> 0 | FO24: =FN24/35*100 -> 0
A25: 14 | B25: TN22SDA894044 | C25: CDT | D25: SATHEESH KUMAR.V | E25: 3 | F25: 6 | G25: 9 | H25: 12 | I25: =COUNT(E25:H25) -> 4 | J25: =I25*2 -> 8 | K25: =I25/4*100 -> 100 | L25: =I25*50 -> 200 | N25: =IF(K25<=40,0,IF(K25<=60,5,IF(K25>=61,10))) -> 10 | P25: =L25 -> 200 | R25: =N25 -> 10 | U25: 14 | V25: TN22SDA894044 | W25: CDT | X25: SATHEESH KUMAR.V | Y25: A | Z25: 15 | AA25: 18 | AB25: 21 | AC25: 24 | AD25: A | AE25: 27 | AF25: 30 | AG25: =COUNT(Y25:AF25) -> 6 | AH25: =AG25*2 -> 12 | AI25: =AG25/8*100 -> 75 | AJ25: =AG25*50 -> 300 | AL25: =IF(AI25<=40,0,IF(AI25<=60,5,IF(AI25>=61,10))) -> 10 | AN25: =P25+AJ25 -> 500 | AP25: =R25+AL25 -> 20 | AS25: 14 | AT25: TN22SDA894044 | AU25: CDT | AV25: SATHEESH KUMAR.V | AW25: 33 | AX25: 36 | AY25: 39 | AZ25: 42 | BA25: A | BB25: 45 | BC25: 48 | BD25: 51 | BE25: =COUNT(AW25:BD25) -> 7 | BF25: =BE25*2 -> 14 | BG25: =BE25/8*100 -> 87.5 | BH25: =BE25*50 -> 350 | BJ25: =IF(BG25<=40,0,IF(BG25<=60,5,IF(BG25>=61,10))) -> 10 | BL25: =AN25+BH25 -> 850 | BN25: =AP25+BJ25 -> 30 | BQ25: 14 | BR25: TN22SDA894044 | BS25: CDT | BT25: SATHEESH KUMAR.V | BU25: 54 | BV25: A | BW25: 57 | BX25: 60 | BY25: =COUNT(BU25:BX25) -> 3 | BZ25: =BY25*2 -> 6 | CA25: =BY25/4*100 -> 75 | CB25: =BY25*50 -> 150 | CD25: =IF(CA25<=40,0,IF(CA25<=60,5,IF(CA25>=61,10))) -> 10 | CF25: =BL25 -> 850 | CK25: 14 | CW25: =COUNT(CO25:CV25) -> 0 | CX25: =CW25*2 -> 0 | CY25: =CW25/5*100 -> 0 | CZ25: =CW25*50 -> 0 | DB25: =IF(CY25<=40,0,IF(CY25<=60,5,IF(CY25>=61,10))) -> 0 | DD25: =CF25+CZ25 -> 850 | DF25: =CH25+DB25 -> 0 | DI25: 14 | DU25: =COUNT(DM25:DT25) -> 0 | DV25: =DU25*2 -> 0 | DW25: =DU25/6*100 -> 0 | DX25: =DU25*50 -> 0 | DZ25: =IF(DW25<=40,0,IF(DW25<=60,5,IF(DW25>=61,10))) -> 0 | EB25: =DD25+DX25 -> 850 | ED25: =DF25+DZ25 -> 0 | EG25: 14 | EH25: TN20SDA894044 | EI25: CDT | EJ25: UDHAYA KAVI M | FA25: =COUNT(EK25:ER25) -> 0 | FB25: =FA25*2 -> 0 | FC25: =FA25/4*100 -> 0 | FD25: =FA25*50 -> 0 | FF25: =IF(FC25<=40,0,IF(FC25<=60,5,IF(FC25>=61,10))) -> 0 | FH25: =EB25+FD25 -> 850 | FJ25: =ED25+FF25 -> 0 | FN25: =EM25/3 -> 0 | FO25: =FN25/35*100 -> 0
A26: 15 | B26: TN22SWA894045 | C26: CDT | D26: ABINAYA.K | E26: 3 | F26: 6 | G26: 9 | H26: 12 | I26: =COUNT(E26:H26) -> 4 | J26: =I26*2 -> 8 | K26: =I26/4*100 -> 100 | L26: =I26*50 -> 200 | N26: =IF(K26<=40,0,IF(K26<=60,5,IF(K26>=61,10))) -> 10 | P26: =L26 -> 200 | R26: =N26 -> 10 | U26: 15 | V26: TN22SWA894045 | W26: CDT | X26: ABINAYA.K | Y26: 9 | Z26: 12 | AA26: 15 | AB26: 18 | AC26: A | AD26: 21 | AE26: 24 | AF26: 27 | AG26: =COUNT(Y26:AF26) -> 7 | AH26: =AG26*2 -> 14 | AI26: =AG26/8*100 -> 87.5 | AJ26: =AG26*50 -> 350 | AL26: =IF(AI26<=40,0,IF(AI26<=60,5,IF(AI26>=61,10))) -> 10 | AN26: =P26+AJ26 -> 550 | AP26: =R26+AL26 -> 20 | AS26: 15 | AT26: TN22SWA894045 | AU26: CDT | AV26: ABINAYA.K | AW26: 30 | AX26: 33 | AY26: A | AZ26: 36 | BA26: 39 | BB26: A | BC26: 42 | BD26: 45 | BE26: =COUNT(AW26:BD26) -> 6 | BF26: =BE26*2 -> 12 | BG26: =BE26/8*100 -> 75 | BH26: =BE26*50 -> 300 | BJ26: =IF(BG26<=40,0,IF(BG26<=60,5,IF(BG26>=61,10))) -> 10 | BL26: =AN26+BH26 -> 850 | BN26: =AP26+BJ26 -> 30 | BQ26: 15 | BR26: TN22SWA894045 | BS26: CDT | BT26: ABINAYA.K | BU26: 48 | BV26: A | BW26: 51 | BX26: 54 | BY26: =COUNT(BU26:BX26) -> 3 | BZ26: =BY26*2 -> 6 | CA26: =BY26/4*100 -> 75 | CB26: =BY26*50 -> 150 | CD26: =IF(CA26<=40,0,IF(CA26<=60,5,IF(CA26>=61,10))) -> 10 | CF26: =BL26 -> 850 | CK26: 15 | CW26: =COUNT(CO26:CV26) -> 0 | CX26: =CW26*2 -> 0 | CY26: =CW26/5*100 -> 0 | CZ26: =CW26*50 -> 0 | DB26: =IF(CY26<=40,0,IF(CY26<=60,5,IF(CY26>=61,10))) -> 0 | DD26: =CF26+CZ26 -> 850 | DF26: =CH26+DB26 -> 0 | DI26: 15 | DU26: =COUNT(DM26:DT26) -> 0 | DV26: =DU26*2 -> 0 | DW26: =DU26/6*100 -> 0 | DX26: =DU26*50 -> 0 | DZ26: =IF(DW26<=40,0,IF(DW26<=60,5,IF(DW26>=61,10))) -> 0 | EB26: =DD26+DX26 -> 850 | ED26: =DF26+DZ26 -> 0 | EG26: 15 | EH26: TN20SDA894045 | EI26: CDT | EJ26: VARATHARAJAN.N | FA26: =COUNT(EK26:ER26) -> 0 | FB26: =FA26*2 -> 0 | FC26: =FA26/4*100 -> 0 | FD26: =FA26*50 -> 0 | FF26: =IF(FC26<=40,0,IF(FC26<=60,5,IF(FC26>=61,10))) -> 0 | FH26: =EB26+FD26 -> 850 | FJ26: =ED26+FF26 -> 0 | FN26: =EN26/3 -> 0 | FO26: =FN26/35*100 -> 0
A27: 16 | B27: TN22SWA894046 | C27: CDT | D27: AISHWARIYA.S | E27: 3 | F27: 6 | G27: 9 | H27: 12 | I27: =COUNT(E27:H27) -> 4 | J27: =I27*2 -> 8 | K27: =I27/4*100 -> 100 | L27: =I27*50 -> 200 | N27: =IF(K27<=40,0,IF(K27<=60,5,IF(K27>=61,10))) -> 10 | P27: =L27 -> 200 | R27: =N27 -> 10 | U27: 16 | V27: TN22SWA894046 | W27: CDT | X27: AISHWARIYA.S | Y27: 15 | Z27: 18 | AA27: 21 | AB27: A | AC27: 24 | AD27: A | AE27: 27 | AF27: 30 | AG27: =COUNT(Y27:AF27) -> 6 | AH27: =AG27*2 -> 12 | AI27: =AG27/8*100 -> 75 | AJ27: =AG27*50 -> 300 | AL27: =IF(AI27<=40,0,IF(AI27<=60,5,IF(AI27>=61,10))) -> 10 | AN27: =P27+AJ27 -> 500 | AP27: =R27+AL27 -> 20 | AS27: 16 | AT27: TN22SWA894046 | AU27: CDT | AV27: AISHWARIYA.S | AW27: 30 | AX27: 33 | AY27: 36 | AZ27: 39 | BA27: A | BB27: 42 | BC27: A | BD27: 45 | BE27: =COUNT(AW27:BD27) -> 6 | BF27: =BE27*2 -> 12 | BG27: =BE27/8*100 -> 75 | BH27: =BE27*50 -> 300 | BJ27: =IF(BG27<=40,0,IF(BG27<=60,5,IF(BG27>=61,10))) -> 10 | BL27: =AN27+BH27 -> 800 | BN27: =AP27+BJ27 -> 30 | BQ27: 16 | BR27: TN22SWA894046 | BS27: CDT | BT27: AISHWARIYA.S | BU27: 48 | BV27: 51 | BW27: 54 | BX27: A | BY27: =COUNT(BU27:BX27) -> 3 | BZ27: =BY27*2 -> 6 | CA27: =BY27/4*100 -> 75 | CB27: =BY27*50 -> 150 | CD27: =IF(CA27<=40,0,IF(CA27<=60,5,IF(CA27>=61,10))) -> 10 | CF27: =BL27 -> 800 | CK27: 16 | CW27: =COUNT(CO27:CV27) -> 0 | CX27: =CW27*2 -> 0 | CY27: =CW27/5*100 -> 0 | CZ27: =CW27*50 -> 0 | DB27: =IF(CY27<=40,0,IF(CY27<=60,5,IF(CY27>=61,10))) -> 0 | DD27: =CF27+CZ27 -> 800 | DF27: =CH27+DB27 -> 0 | DI27: 16 | DU27: =COUNT(DM27:DT27) -> 0 | DV27: =DU27*2 -> 0 | DW27: =DU27/6*100 -> 0 | DX27: =DU27*50 -> 0 | DZ27: =IF(DW27<=40,0,IF(DW27<=60,5,IF(DW27>=61,10))) -> 0 | EB27: =DD27+DX27 -> 800 | ED27: =DF27+DZ27 -> 0 | EG27: 16 | EH27: TN20SDA894046 | EI27: CPL | EJ27: VINODKUMAR.K.S | FA27: =COUNT(EK27:ER27) -> 0 | FB27: =FA27*2 -> 0 | FC27: =FA27/4*100 -> 0 | FD27: =FA27*50 -> 0 | FF27: =IF(FC27<=40,0,IF(FC27<=60,5,IF(FC27>=61,10))) -> 0 | FH27: =EB27+FD27 -> 800 | FJ27: =ED27+FF27 -> 0 | FN27: =EN27/3 -> 0 | FO27: =FN27/35*100 -> 0
A28: 17 | B28: TN22SWA894047 | C28: CDT | D28: ARUNA.R | E28: A | F28: A | G28: A | H28: A | I28: =COUNT(E28:H28) -> 0 | J28: =I28*2 -> 0 | K28: =I28/4*100 -> 0 | L28: =I28*50 -> 0 | N28: =IF(K28<=40,0,IF(K28<=60,5,IF(K28>=61,10))) -> 0 | P28: =L28 -> 0 | R28: =N28 -> 0 | U28: 17 | V28: TN22SWA894047 | W28: CDT | X28: ARUNA.R | Y28: 3 | Z28: 6 | AA28: 9 | AB28: 12 | AC28: 15 | AD28: 18 | AE28: 21 | AF28: A | AG28: =COUNT(Y28:AF28) -> 7 | AH28: =AG28*2 -> 14 | AI28: =AG28/8*100 -> 87.5 | AJ28: =AG28*50 -> 350 | AL28: =IF(AI28<=40,0,IF(AI28<=60,5,IF(AI28>=61,10))) -> 10 | AN28: =P28+AJ28 -> 350 | AP28: =R28+AL28 -> 10 | AS28: 17 | AT28: TN22SWA894047 | AU28: CDT | AV28: ARUNA.R | AW28: A | AX28: A | AY28: 24 | AZ28: 27 | BA28: 30 | BB28: 33 | BC28: 36 | BD28: 39 | BE28: =COUNT(AW28:BD28) -> 6 | BF28: =BE28*2 -> 12 | BG28: =BE28/8*100 -> 75 | BH28: =BE28*50 -> 300 | BJ28: =IF(BG28<=40,0,IF(BG28<=60,5,IF(BG28>=61,10))) -> 10 | BL28: =AN28+BH28 -> 650 | BN28: =AP28+BJ28 -> 20 | BQ28: 17 | BR28: TN22SWA894047 | BS28: CDT | BT28: ARUNA.R | BU28: 42 | BV28: 45 | BW28: 48 | BX28: 51 | BY28: =COUNT(BU28:BX28) -> 4 | BZ28: =BY28*2 -> 8 | CA28: =BY28/4*100 -> 100 | CB28: =BY28*50 -> 200 | CD28: =IF(CA28<=40,0,IF(CA28<=60,5,IF(CA28>=61,10))) -> 10 | CF28: =BL28 -> 650 | CK28: 17 | CW28: =COUNT(CO28:CV28) -> 0 | CX28: =CW28*2 -> 0 | CY28: =CW28/5*100 -> 0 | CZ28: =CW28*50 -> 0 | DB28: =IF(CY28<=40,0,IF(CY28<=60,5,IF(CY28>=61,10))) -> 0 | DD28: =CF28+CZ28 -> 650 | DF28: =CH28+DB28 -> 0 | DI28: 17 | DU28: =COUNT(DM28:DT28) -> 0 | DV28: =DU28*2 -> 0 | DW28: =DU28/6*100 -> 0 | DX28: =DU28*50 -> 0 | DZ28: =IF(DW28<=40,0,IF(DW28<=60,5,IF(DW28>=61,10))) -> 0 | EB28: =DD28+DX28 -> 650 | ED28: =DF28+DZ28 -> 0 | EG28: 17 | EH28: TN20SWA894047 | EI28: CDT | EJ28: KAVYA. R | FA28: =COUNT(EK28:ER28) -> 0 | FB28: =FA28*2 -> 0 | FC28: =FA28/4*100 -> 0 | FD28: =FA28*50 -> 0 | FF28: =IF(FC28<=40,0,IF(FC28<=60,5,IF(FC28>=61,10))) -> 0 | FH28: =EB28+FD28 -> 650 | FJ28: =ED28+FF28 -> 0 | FN28: =EN28/3 -> 0 | FO28: =FN28/35*100 -> 0
A29: 18 | B29: TN22SWA894048 | C29: CDT | D29: ASWATHI.E | E29: 3 | F29: 6 | G29: 9 | H29: 12 | I29: =COUNT(E29:H29) -> 4 | J29: =I29*2 -> 8 | K29: =I29/4*100 -> 100 | L29: =I29*50 -> 200 | N29: =IF(K29<=40,0,IF(K29<=60,5,IF(K29>=61,10))) -> 10 | P29: =L29 -> 200 | R29: =N29 -> 10 | U29: 18 | V29: TN22SWA894048 | W29: CDT | X29: ASWATHI.E | Y29: 12 | Z29: 15 | AA29: 18 | AB29: 21 | AC29: 24 | AD29: 27 | AE29: A | AF29: A | AG29: =COUNT(Y29:AF29) -> 6 | AH29: =AG29*2 -> 12 | AI29: =AG29/8*100 -> 75 | AJ29: =AG29*50 -> 300 | AL29: =IF(AI29<=40,0,IF(AI29<=60,5,IF(AI29>=61,10))) -> 10 | AN29: =P29+AJ29 -> 500 | AP29: =R29+AL29 -> 20 | AS29: 18 | AT29: TN22SWA894048 | AU29: CDT | AV29: ASWATHI.E | AW29: A | AX29: 9 | AY29: 12 | AZ29: 15 | BA29: 18 | BB29: A | BC29: 21 | BD29: 24 | BE29: =COUNT(AW29:BD29) -> 6 | BF29: =BE29*2 -> 12 | BG29: =BE29/8*100 -> 75 | BH29: =BE29*50 -> 300 | BJ29: =IF(BG29<=40,0,IF(BG29<=60,5,IF(BG29>=61,10))) -> 10 | BL29: =AN29+BH29 -> 800 | BN29: =AP29+BJ29 -> 30 | BQ29: 18 | BR29: TN22SWA894048 | BS29: CDT | BT29: ASWATHI.E | BU29: A | BV29: A | BW29: 27 | BX29: 30 | BY29: =COUNT(BU29:BX29) -> 2 | BZ29: =BY29*2 -> 4 | CA29: =BY29/4*100 -> 50 | CB29: =BY29*50 -> 100 | CD29: =IF(CA29<=40,0,IF(CA29<=60,5,IF(CA29>=61,10))) -> 5 | CF29: =BL29 -> 800 | CK29: 18 | CW29: =COUNT(CO29:CV29) -> 0 | CX29: =CW29*2 -> 0 | CY29: =CW29/5*100 -> 0 | CZ29: =CW29*50 -> 0 | DB29: =IF(CY29<=40,0,IF(CY29<=60,5,IF(CY29>=61,10))) -> 0 | DD29: =CF29+CZ29 -> 800 | DF29: =CH29+DB29 -> 0 | DI29: 18 | DU29: =COUNT(DM29:DT29) -> 0 | DV29: =DU29*2 -> 0 | DW29: =DU29/6*100 -> 0 | DX29: =DU29*50 -> 0 | DZ29: =IF(DW29<=40,0,IF(DW29<=60,5,IF(DW29>=61,10))) -> 0 | EB29: =DD29+DX29 -> 800 | ED29: =DF29+DZ29 -> 0 | EG29: 18 | EH29: TN20SWA894048 | EI29: CUO | EJ29: LEENA N | FA29: =COUNT(EK29:ER29) -> 0 | FB29: =FA29*2 -> 0 | FC29: =FA29/4*100 -> 0 | FD29: =FA29*50 -> 0 | FF29: =IF(FC29<=40,0,IF(FC29<=60,5,IF(FC29>=61,10))) -> 0 | FH29: =EB29+FD29 -> 800 | FJ29: =ED29+FF29 -> 0 | FN29: =EN29/3 -> 0 | FO29: =FN29/35*100 -> 0
A30: 19 | B30: TN22SWA894049 | C30: CDT | D30: GUNASELVAM.G | E30: 3 | F30: 6 | G30: 9 | H30: 12 | I30: =COUNT(E30:H30) -> 4 | J30: =I30*2 -> 8 | K30: =I30/4*100 -> 100 | L30: =I30*50 -> 200 | N30: =IF(K30<=40,0,IF(K30<=60,5,IF(K30>=61,10))) -> 10 | P30: =L30 -> 200 | R30: =N30 -> 10 | U30: 19 | V30: TN22SWA894049 | W30: CDT | X30: GUNASELVAM.G | Y30: A | Z30: 12 | AA30: 15 | AB30: 18 | AC30: A | AD30: 21 | AE30: 24 | AF30: 27 | AG30: =COUNT(Y30:AF30) -> 6 | AH30: =AG30*2 -> 12 | AI30: =AG30/8*100 -> 75 | AJ30: =AG30*50 -> 300 | AL30: =IF(AI30<=40,0,IF(AI30<=60,5,IF(AI30>=61,10))) -> 10 | AN30: =P30+AJ30 -> 500 | AP30: =R30+AL30 -> 20 | AS30: 19 | AT30: TN22SWA894049 | AU30: CDT | AV30: GUNASELVAM.G | AW30: 30 | AX30: 33 | AY30: 36 | AZ30: A | BA30: 39 | BB30: 42 | BC30: A | BD30: 45 | BE30: =COUNT(AW30:BD30) -> 6 | BF30: =BE30*2 -> 12 | BG30: =BE30/8*100 -> 75 | BH30: =BE30*50 -> 300 | BJ30: =IF(BG30<=40,0,IF(BG30<=60,5,IF(BG30>=61,10))) -> 10 | BL30: =AN30+BH30 -> 800 | BN30: =AP30+BJ30 -> 30 | BQ30: 19 | BR30: TN22SWA894049 | BS30: CDT | BT30: GUNASELVAM.G | BU30: 48 | BV30: 51 | BW30: 54 | BX30: 57 | BY30: =COUNT(BU30:BX30) -> 4 | BZ30: =BY30*2 -> 8 | CA30: =BY30/4*100 -> 100 | CB30: =BY30*50 -> 200 | CD30: =IF(CA30<=40,0,IF(CA30<=60,5,IF(CA30>=61,10))) -> 10 | CF30: =BL30 -> 800 | CK30: 19 | CW30: =COUNT(CO30:CV30) -> 0 | CX30: =CW30*2 -> 0 | CY30: =CW30/5*100 -> 0 | CZ30: =CW30*50 -> 0 | DB30: =IF(CY30<=40,0,IF(CY30<=60,5,IF(CY30>=61,10))) -> 0 | DD30: =CF30+CZ30 -> 800 | DF30: =CH30+DB30 -> 0 | DI30: 19 | DU30: =COUNT(DM30:DT30) -> 0 | DV30: =DU30*2 -> 0 | DW30: =DU30/6*100 -> 0 | DX30: =DU30*50 -> 0 | DZ30: =IF(DW30<=40,0,IF(DW30<=60,5,IF(DW30>=61,10))) -> 0 | EB30: =DD30+DX30 -> 800 | ED30: =DF30+DZ30 -> 0 | EG30: 19 | EH30: TN20SWA894049 | EI30: LCPL | EJ30: MAHEEMA R | FA30: =COUNT(EK30:ER30) -> 0 | FB30: =FA30*2 -> 0 | FC30: =FA30/4*100 -> 0 | FD30: =FA30*50 -> 0 | FF30: =IF(FC30<=40,0,IF(FC30<=60,5,IF(FC30>=61,10))) -> 0 | FH30: =EB30+FD30 -> 800 | FJ30: =ED30+FF30 -> 0 | FN30: =EN30/3 -> 0 | FO30: =FN30/35*100 -> 0
A31: 20 | B31: TN22SWA894050 | C31: CDT | D31: INDHUMATHI.V | E31: 3 | F31: 6 | G31: 9 | H31: 12 | I31: =COUNT(E31:H31) -> 4 | J31: =I31*2 -> 8 | K31: =I31/4*100 -> 100 | L31: =I31*50 -> 200 | N31: =IF(K31<=40,0,IF(K31<=60,5,IF(K31>=61,10))) -> 10 | P31: =L31 -> 200 | R31: =N31 -> 10 | U31: 20 | V31: TN22SWA894050 | W31: CDT | X31: INDHUMATHI.V | Y31: 15 | Z31: 18 | AA31: A | AB31: 21 | AC31: 24 | AD31: 27 | AE31: A | AF31: 30 | AG31: =COUNT(Y31:AF31) -> 6 | AH31: =AG31*2 -> 12 | AI31: =AG31/8*100 -> 75 | AJ31: =AG31*50 -> 300 | AL31: =IF(AI31<=40,0,IF(AI31<=60,5,IF(AI31>=61,10))) -> 10 | AN31: =P31+AJ31 -> 500 | AP31: =R31+AL31 -> 20 | AS31: 20 | AT31: TN22SWA894050 | AU31: CDT | AV31: INDHUMATHI.V | AW31: 33 | AX31: 36 | AY31: A | AZ31: 39 | BA31: 42 | BB31: 45 | BC31: 48 | BD31: A | BE31: =COUNT(AW31:BD31) -> 6 | BF31: =BE31*2 -> 12 | BG31: =BE31/8*100 -> 75 | BH31: =BE31*50 -> 300 | BJ31: =IF(BG31<=40,0,IF(BG31<=60,5,IF(BG31>=61,10))) -> 10 | BL31: =AN31+BH31 -> 800 | BN31: =AP31+BJ31 -> 30 | BQ31: 20 | BR31: TN22SWA894050 | BS31: CDT | BT31: INDHUMATHI.V | BU31: 51 | BV31: A | BW31: 54 | BX31: 57 | BY31: =COUNT(BU31:BX31) -> 3 | BZ31: =BY31*2 -> 6 | CA31: =BY31/4*100 -> 75 | CB31: =BY31*50 -> 150 | CD31: =IF(CA31<=40,0,IF(CA31<=60,5,IF(CA31>=61,10))) -> 10 | CF31: =BL31 -> 800 | CK31: 20 | CW31: =COUNT(CO31:CV31) -> 0 | CX31: =CW31*2 -> 0 | CY31: =CW31/5*100 -> 0 | CZ31: =CW31*50 -> 0 | DB31: =IF(CY31<=40,0,IF(CY31<=60,5,IF(CY31>=61,10))) -> 0 | DD31: =CF31+CZ31 -> 800 | DF31: =CH31+DB31 -> 0 | DI31: 20 | DU31: =COUNT(DM31:DT31) -> 0 | DV31: =DU31*2 -> 0 | DW31: =DU31/6*100 -> 0 | DX31: =DU31*50 -> 0 | DZ31: =IF(DW31<=40,0,IF(DW31<=60,5,IF(DW31>=61,10))) -> 0 | EB31: =DD31+DX31 -> 800 | ED31: =DF31+DZ31 -> 0 | EG31: 20 | EH31: TN20SWA894050 | EI31: CDT | EJ31: RAGAVI A | FA31: =COUNT(EK31:ER31) -> 0 | FB31: =FA31*2 -> 0 | FC31: =FA31/4*100 -> 0 | FD31: =FA31*50 -> 0 | FF31: =IF(FC31<=40,0,IF(FC31<=60,5,IF(FC31>=61,10))) -> 0 | FH31: =EB31+FD31 -> 800 | FJ31: =ED31+FF31 -> 0 | FN31: =EN31/3 -> 0 | FO31: =FN31/35*100 -> 0
A32: 21 | B32: TN22SWA894051 | C32: CDT | D32: MITHRA.V | E32: 3 | F32: A | G32: 6 | H32: A | I32: =COUNT(E32:H32) -> 2 | J32: =I32*2 -> 4 | K32: =I32/4*100 -> 50 | L32: =I32*50 -> 100 | N32: =IF(K32<=40,0,IF(K32<=60,5,IF(K32>=61,10))) -> 5 | P32: =L32 -> 100 | R32: =N32 -> 5 | U32: 21 | V32: TN22SWA894051 | W32: CDT | X32: MITHRA.V | Y32: A | Z32: 12 | AA32: A | AB32: A | AC32: A | AD32: A | AE32: A | AF32: 15 | AG32: =COUNT(Y32:AF32) -> 2 | AH32: =AG32*2 -> 4 | AI32: =AG32/8*100 -> 25 | AJ32: =AG32*50 -> 100 | AL32: =IF(AI32<=40,0,IF(AI32<=60,5,IF(AI32>=61,10))) -> 0 | AN32: =P32+AJ32 -> 200 | AP32: =R32+AL32 -> 5 | AS32: 21 | AT32: TN22SWA894051 | AU32: CDT | AV32: MITHRA.V | AW32: 33 | AX32: A | AY32: 36 | AZ32: A | BA32: A | BB32: A | BC32: 39 | BD32: 42 | BE32: =COUNT(AW32:BD32) -> 4 | BF32: =BE32*2 -> 8 | BG32: =BE32/8*100 -> 50 | BH32: =BE32*50 -> 200 | BJ32: =IF(BG32<=40,0,IF(BG32<=60,5,IF(BG32>=61,10))) -> 5 | BL32: =AN32+BH32 -> 400 | BN32: =AP32+BJ32 -> 10 | BQ32: 21 | BR32: TN22SWA894051 | BS32: CDT | BT32: MITHRA.V | BU32: A | BV32: 45 | BW32: A | BX32: 48 | BY32: =COUNT(BU32:BX32) -> 2 | BZ32: =BY32*2 -> 4 | CA32: =BY32/4*100 -> 50 | CB32: =BY32*50 -> 100 | CD32: =IF(CA32<=40,0,IF(CA32<=60,5,IF(CA32>=61,10))) -> 5 | CF32: =BL32 -> 400 | CK32: 21 | CW32: =COUNT(CO32:CV32) -> 0 | CX32: =CW32*2 -> 0 | CY32: =CW32/5*100 -> 0 | CZ32: =CW32*50 -> 0 | DB32: =IF(CY32<=40,0,IF(CY32<=60,5,IF(CY32>=61,10))) -> 0 | DD32: =CF32+CZ32 -> 400 | DF32: =CH32+DB32 -> 0 | DI32: 21 | DU32: =COUNT(DM32:DT32) -> 0 | DV32: =DU32*2 -> 0 | DW32: =DU32/6*100 -> 0 | DX32: =DU32*50 -> 0 | DZ32: =IF(DW32<=40,0,IF(DW32<=60,5,IF(DW32>=61,10))) -> 0 | EB32: =DD32+DX32 -> 400 | ED32: =DF32+DZ32 -> 0 | EG32: 21 | EH32: TN20SWA894051 | EI32: SGT | EJ32: SANTHIYA S | FA32: =COUNT(EK32:ER32) -> 0 | FB32: =FA32*2 -> 0 | FC32: =FA32/4*100 -> 0 | FD32: =FA32*50 -> 0 | FF32: =IF(FC32<=40,0,IF(FC32<=60,5,IF(FC32>=61,10))) -> 0 | FH32: =EB32+FD32 -> 400 | FJ32: =ED32+FF32 -> 0 | FN32: =EN32/3 -> 0 | FO32: =FN32/35*100 -> 0
A33: 22 | B33: TN22SWA894052 | C33: CDT | D33: RIYA ROSARIN.B | E33: 3 | F33: A | G33: 6 | H33: 12 | I33: =COUNT(E33:H33) -> 3 | J33: =I33*2 -> 6 | K33: =I33/4*100 -> 75 | L33: =I33*50 -> 150 | N33: =IF(K33<=40,0,IF(K33<=60,5,IF(K33>=61,10))) -> 10 | P33: =L33 -> 150 | R33: =N33 -> 10 | U33: 22 | V33: TN22SWA894052 | W33: CDT | X33: RIYA ROSARIN.B | Y33: A | Z33: A | AA33: 12 | AB33: A | AC33: 15 | AD33: A | AE33: 18 | AF33: A | AG33: =COUNT(Y33:AF33) -> 3 | AH33: =AG33*2 -> 6 | AI33: =AG33/8*100 -> 37.5 | AJ33: =AG33*50 -> 150 | AL33: =IF(AI33<=40,0,IF(AI33<=60,5,IF(AI33>=61,10))) -> 0 | AN33: =P33+AJ33 -> 300 | AP33: =R33+AL33 -> 10 | AS33: 22 | AT33: TN22SWA894052 | AU33: CDT | AV33: RIYA ROSARIN.B | AW33: 21 | AX33: 24 | AY33: 27 | AZ33: 30 | BA33: 33 | BB33: A | BC33: A | BD33: A | BE33: =COUNT(AW33:BD33) -> 5 | BF33: =BE33*2 -> 10 | BG33: =BE33/8*100 -> 62.5 | BH33: =BE33*50 -> 250 | BJ33: =IF(BG33<=40,0,IF(BG33<=60,5,IF(BG33>=61,10))) -> 10 | BL33: =AN33+BH33 -> 550 | BN33: =AP33+BJ33 -> 20 | BQ33: 22 | BR33: TN22SWA894052 | BS33: CDT | BT33: RIYA ROSARIN.B | BU33: 36 | BV33: 39 | BW33: 42 | BX33: A | BY33: =COUNT(BU33:BX33) -> 3 | BZ33: =BY33*2 -> 6 | CA33: =BY33/4*100 -> 75 | CB33: =BY33*50 -> 150 | CD33: =IF(CA33<=40,0,IF(CA33<=60,5,IF(CA33>=61,10))) -> 10 | CF33: =BL33 -> 550 | CK33: 22 | CW33: =COUNT(CO33:CV33) -> 0 | CX33: =CW33*2 -> 0 | CY33: =CW33/5*100 -> 0 | CZ33: =CW33*50 -> 0 | DB33: =IF(CY33<=40,0,IF(CY33<=60,5,IF(CY33>=61,10))) -> 0 | DD33: =CF33+CZ33 -> 550 | DF33: =CH33+DB33 -> 0 | DI33: 22 | DU33: =COUNT(DM33:DT33) -> 0 | DV33: =DU33*2 -> 0 | DW33: =DU33/6*100 -> 0 | DX33: =DU33*50 -> 0 | DZ33: =IF(DW33<=40,0,IF(DW33<=60,5,IF(DW33>=61,10))) -> 0 | EB33: =DD33+DX33 -> 550 | ED33: =DF33+DZ33 -> 0 | EG33: 22 | EH33: TN20SWA894052 | EI33: CPL | EJ33: SUBANITHI B | FA33: =COUNT(EK33:ER33) -> 0 | FB33: =FA33*2 -> 0 | FC33: =FA33/4*100 -> 0 | FD33: =FA33*50 -> 0 | FF33: =IF(FC33<=40,0,IF(FC33<=60,5,IF(FC33>=61,10))) -> 0 | FH33: =EB33+FD33 -> 550 | FJ33: =ED33+FF33 -> 0 | FN33: =EN33/3 -> 0 | FO33: =FN33/35*100 -> 0
E34: =COUNT(E12:E33) -> 17 | F34: =COUNT(F12:F33) -> 14 | G34: =COUNT(G12:G33) -> 16 | H34: =COUNT(H12:H33) -> 14 | Y34: =COUNT(Y12:Y33) -> 15 | Z34: =COUNT(Z12:Z33) -> 17 | AA34: =COUNT(AA12:AA33) -> 16 | AB34: =COUNT(AB12:AB33) -> 15 | AC34: =COUNT(AC12:AC33) -> 15 | AD34: =COUNT(AD12:AD33) -> 15 | AE34: =COUNT(AE12:AE33) -> 15 | AF34: =COUNT(AF12:AF33) -> 15 | AW34: =COUNT(AW12:AW33) -> 14 | AX34: =COUNT(AX12:AX33) -> 15 | AY34: =COUNT(AY12:AY33) -> 14 | AZ34: =COUNT(AZ12:AZ33) -> 16 | BA34: =COUNT(BA12:BA33) -> 14 | BB34: =COUNT(BB12:BB33) -> 14 | BC34: =COUNT(BC12:BC33) -> 15 | BD34: =COUNT(BD12:BD33) -> 15 | BU34: =COUNT(BU12:BU33) -> 14 | BV34: =COUNT(BV12:BV33) -> 15 | BW34: =COUNT(BW12:BW33) -> 16 | BX34: =COUNT(BX12:BX33) -> 14 | CF34: =BL34 -> 0 | CO34: =COUNT(CO12:CO33) -> 0 | CP34: =COUNT(CP12:CP33) -> 0 | CQ34: =COUNT(CQ12:CQ33) -> 0 | CR34: =COUNT(CR12:CR33) -> 0 | CS34: =COUNT(CS12:CS33) -> 0 | DM34: =COUNT(DM12:DM33) -> 0 | DN34: =COUNT(DN12:DN33) -> 0 | DO34: =COUNT(DO12:DO33) -> 0 | DP34: =COUNT(DP12:DP33) -> 0 | DQ34: =COUNT(DQ12:DQ33) -> 0 | DR34: =COUNT(DR12:DR33) -> 0 | DS34: =COUNT(DS12:DS33) -> 0 | EK34: =COUNT(EK12:EK33) -> 0 | EL34: =COUNT(EL12:EL33) -> 0 | EM34: =COUNT(EM12:EM33) -> 0 | EN34: =COUNT(EN12:EN33) -> 0
E35: =E34*50 -> 850 | F35: =F34*50 -> 700 | G35: =G34*50 -> 800 | H35: =H34*50 -> 700 | Y35: =Y34*50 -> 750 | Z35: =Z34*50 -> 850 | AA35: =AA34*50 -> 800 | AB35: =AB34*50 -> 750 | AC35: =AC34*50 -> 750 | AD35: =AD34*50 -> 750 | AE35: =AE34*50 -> 750 | AF35: =AF34*50 -> 750 | AW35: =AW34*50 -> 700 | AX35: =AX34*50 -> 750 | AY35: =AY34*50 -> 700 | AZ35: =AZ34*50 -> 800 | BA35: =BA34*50 -> 700 | BB35: =BB34*50 -> 700 | BC35: =BC34*50 -> 750 | BD35: =BD34*50 -> 750 | BU35: =BU34*20 -> 280 | BV35: =BV34*20 -> 300 | BW35: =BW34*20 -> 320 | BX35: =BX34*20 -> 280 | CF35: =BL35 -> 0 | CO35: =CO34*50 -> 0 | CP35: =CP34*50 -> 0 | CQ35: =CQ34*50 -> 0 | CR35: =CR34*50 -> 0 | CS35: =CS34*50 -> 0 | DM35: =DM34*50 -> 0 | DN35: =DN34*50 -> 0 | DO35: =DO34*50 -> 0 | DP35: =DP34*50 -> 0 | DQ35: =DQ34*50 -> 0 | DR35: =DR34*50 -> 0 | DS35: =DS34*20 -> 0 | EK35: =EK34*50 -> 0 | EL35: =EL34*50 -> 0 | EM35: =EM34*50 -> 0 | EN35: =EN34*50 -> 0 | FH35: =SUM(FH12:FH33) -> 15050 | FN35: Wash Allw | FO35: =SUM(FJ12:FJ33) -> 0
G37: =SUM(E34:H34) -> 61 | AF37: =SUM(Y34:AF34) -> 123 | BD37: =SUM(AW34:BD34) -> 117 | BW37: =SUM(BU34:BX34) -> 59
G38: =G37*50 -> 3050 | AF38: =AF37*50 -> 6150 | BD38: =BD37*50 -> 5850 | BW38: =BW37*50 -> 2950
D43: NATIONAL CADET CORPS | X43: NATIONAL CADET CORPS | AV43: NATIONAL CADET CORPS | BT43: NATIONAL CADET CORPS | CN43: NATIONAL CADET CORPS | DL43: NATIONAL CADET CORPS | EJ43: NATIONAL CADET CORPS
A44: Unit:4 (TN) CTC NCC, Annamalainagar | L44: Place: | M44: Annamalainagar | U44: Unit:4 (TN) CTC NCC, Annamalainagar | AJ44: Place: | AK44: Annamalainagar | AS44: Unit:4 (TN) CTC NCC, Annamalainagar | BH44: Place: | BI44: Annamalainagar | BQ44: Unit:4 (TN) CTC NCC, Annamalainagar | CB44: Place: | CC44: Annamalainagar | CK44: Unit:4 (TN) CTC NCC, Annamalainagar | CZ44: Place: | DA44: Annamalainagar | DI44: Unit:4 (TN) CTC NCC, Annamalainagar | DX44: Place: | DY44: Annamalainagar | EG44: Unit:4 (TN) CTC NCC, Annamalainagar | FD44: Place: | FE44: Annamalainagar
D45: Attendance Register for the month of JULY 2023 | I45: Total number of Parades held in this month: | P45: No.:4 In Hrs:8 | X45: Attendance Register for the month of AUGUST 2023 | AG45: Total number of Parades held in this month: | AN45: No.:8 In Hrs:16 | AV45: Attendance Register for the month of SEPTEMBER 2023 | BE45: Total number of Parades held in this month: | BL45: No.:6 In Hrs:12 | BT45: Attendance Register for the month of OCTOBER 2023 | BY45: Total number of Parades held in this month: | CF45: No.: 4 In Hrs: 8 | CN45: Attendance Register for the month of December 2022 | CW45: Total number of Parades held in this month: | DD45: No.:5 In Hrs:10 | DL45: Attendance Register for the month of January 2023 | DU45: Total number of Parades held in this month: | EB45: No.:6 In Hrs:12 | EJ45: Attendance Register for the month of February 2023 | FA45: Total number of Parades held in this month: | FH45: No.:4 In Hrs:8
A46: College/Institution: | D46: FEAT,Annamalai University (SIGNAL) | U46: College/Institution: | X46: FEAT,Annamalai University (SIGNAL) | AS46: College/Institution: | AV46: FEAT,Annamalai University (SIGNAL) | BQ46: College/Institution: | BT46: FEAT,Annamalai University (EME) | CK46: College/Institution: | CN46: FEAT,Annamalai University (EME) | DI46: College/Institution: | DL46: FEAT,Annamalai University (Signal) | EG46: College/Institution: | EJ46: FEAT,Annamalai University (Signal)
A48: Serial number | B48: Cadet number | C48: Rank | D48: Name | E48: Date of Parades | I48: Total number of Parades | K48: Percentage of Attendance | L48: Allowance due to cadets for the month | P48: Progressive total including amount claimed in this bill | T48: Remarks | U48: Serial number | V48: Cadet number | W48: Rank | X48: Name | Y48: Date of Parades | AG48: Total number of Parades | AI48: Percentage of Attendance | AJ48: Allowance due to cadets for the month | AN48: Progressive total including amount claimed in this bill | AR48: Remarks | AS48: Serial number | AT48: Cadet number | AU48: Rank | AV48: Name | AW48: Date of Parades | BE48: Total number of Parades | BG48: Percentage of Attendance | BH48: Allowance due to cadets for the month | BL48: Progressive total including amount claimed in this bill | BP48: Remarks | BQ48: Serial number | BR48: Cadet number | BS48: Rank | BT48: Name | BU48: Date of Parades | BY48: Total number of Parades | CA48: Percentage of Attendance | CB48: Allowance due to cadets for the month | CF48: Progressive total including amount claimed in this bill | CJ48: Remarks | CK48: Serial number | CL48: Cadet number | CM48: Rank | CN48: Name | CP48: Date of Parades | CW48: Total number of Parades | CY48: Percentage of Attendance | CZ48: Allowance due to cadets for the month | DD48: Progressive total including amount claimed in this bill | DH48: Remarks | DI48: Serial number | DJ48: Cadet number | DK48: Rank | DL48: Name | DM48: Date of Parades | DU48: Total number of Parades | DW48: Percentage of Attendance | DX48: Allowance due to cadets for the month | EB48: Progressive total including amount claimed in this bill | EF48: Remarks | EG48: Serial number | EH48: Cadet number | EI48: Rank | EJ48: Name | EK48: Date of Parades | FA48: Total number of Parades | FC48: Percentage of Attendance | FD48: Allowance due to cadets for the month | FH48: Progressive total including amount claimed in this bill | FL48: Remarks
...

Sheet Sheet1
H1: 4 (TN) Comp Tech Coy NCC,Annamalainagar | O1: 4 (TN) Comp Tech Coy NCC,Annamalainagar | V1: 4 (TN) Comp Tech Coy NCC,Annamalainagar
A2: BILL FOR SUPPLY OF REFERESHMENTS TO THE NCC SD CADETS | H2: BILL FOR SUPPLY OF REFERESHMENTS TO THE NCC SD CADETS | O2: BILL FOR SUPPLY OF REFERESHMENTS TO THE NCC SD CADETS | V2: BILL FOR SUPPLY OF REFERESHMENTS TO THE NCC SD CADETS
A3: OF FEAT (Engg) | D3: FOR THE MONTH OF : AUGUEST 2018 | H3: OF FEAT (Engg) | K3: FOR THE MONTH OF : SEPTEMBER 2018 | O3: OF FEAT (Engg) | R3: FOR THE MONTH OF : OCTOBER 2018 | V3: OF FEAT (Engg) | Y3: FOR THE MONTH OF : NOVEMBER 2018
A5: SL. No. | B5: DATE ON WHICH REFRESHMENTS SUPPLIED | C5: NO OF CADETS SERVED | D5: ITEM OF REFRESHMENTS SUPPLIED | E5: QUANTITY | F5: RATE PER ITEM | G5: AMOUNT | H5: SL. No. | I5: DATE ON WHICH REFRESHMENTS SUPPLIED | J5: NO OF CADETS SERVED | K5: ITEM OF REFRESHMENTS SUPPLIED | L5: QUANTITY | M5: RATE PER ITEM | N5: AMOUNT | O5: SL. No. | P5: DATE ON WHICH REFRESHMENTS SUPPLIED | Q5: NO OF CADETS SERVED | R5: ITEM OF REFRESHMENTS SUPPLIED | S5: QUANTITY | T5: RATE PER ITEM | U5: AMOUNT | V5: SL. No. | W5: DATE ON WHICH REFRESHMENTS SUPPLIED | X5: NO OF CADETS SERVED | Y5: ITEM OF REFRESHMENTS SUPPLIED | Z5: QUANTITY | AA5: RATE PER ITEM | AB5: AMOUNT
A6: 1 | G6: =C6*50 -> 0 | H6: 1 | N6: =J6*50 -> 0 | O6: 1 | U6: =Q6*50 -> 0 | AB6: =X6*20 -> 0
A8: 2 | G8: =C8*50 -> 0 | H8: 2 | N8: =J8*50 -> 0 | O8: 2 | U8: =Q8*50 -> 0 | AB8: =X8*20 -> 0
A10: 3 | G10: =C10*50 -> 0 | H10: 3 | N10: =J10*50 -> 0 | O10: 3 | U10: =Q10*50 -> 0 | AB10: =X10*20 -> 0
A12: 4 | G12: =C12*50 -> 0 | H12: 4 | N12: =J12*50 -> 0 | O12: 4 | U12: =Q12*50 -> 0 | AB12: =X12*20 -> 0
A14: 5 | G14: =C14*50 -> 0 | H14: 5 | N14: =J14*50 -> 0 | O14: 5 | U14: =Q14*50 -> 0 | AB14: =X14*20 -> 0
